Workbook

Sheet Site Wide
A1: Date and Time | B1: Sitewide savings | C1: Current BD | D1: Optimised BD | E1: Current Bore | F1: Optimised Bore | G1: Current KWRP | H1: Optimised KWRP
A2: 44197 | B2: ='N1'!AT2+'N2'!AT2+'N3'!AT2+'P2'!AT2+'A2'!AT2+'A3'!AR2 -> 18.212514
A3: 44197.021 | B3: ='N1'!AT3+'N2'!AT3+'N3'!AT3+'P2'!AT3+'A2'!AT3+'A3'!AR3 -> 42.587096
A4: 44197.042 | B4: ='N1'!AT4+'N2'!AT4+'N3'!AT4+'P2'!AT4+'A2'!AT4+'A3'!AR4 -> 19.781396
A5: 44197.062 | B5: ='N1'!AT5+'N2'!AT5+'N3'!AT5+'P2'!AT5+'A2'!AT5+'A3'!AR5 -> 47.920753
A6: 44197.083 | B6: ='N1'!AT6+'N2'!AT6+'N3'!AT6+'P2'!AT6+'A2'!AT6+'A3'!AR6 -> 62.216821
A7: 44197.104 | B7: ='N1'!AT7+'N2'!AT7+'N3'!AT7+'P2'!AT7+'A2'!AT7+'A3'!AR7 -> 51.751493
A8: 44197.125 | B8: ='N1'!AT8+'N2'!AT8+'N3'!AT8+'P2'!AT8+'A2'!AT8+'A3'!AR8 -> 48.977331
A9: 44197.146 | B9: ='N1'!AT9+'N2'!AT9+'N3'!AT9+'P2'!AT9+'A2'!AT9+'A3'!AR9 -> 39.434378
A10: 44197.167 | B10: ='N1'!AT10+'N2'!AT10+'N3'!AT10+'P2'!AT10+'A2'!AT10+'A3'!AR10 -> 20.031988
A11: 44197.188 | B11: ='N1'!AT11+'N2'!AT11+'N3'!AT11+'P2'!AT11+'A2'!AT11+'A3'!AR11 -> 43.162591
A12: 44197.208 | B12: ='N1'!AT12+'N2'!AT12+'N3'!AT12+'P2'!AT12+'A2'!AT12+'A3'!AR12 -> 22.333035
A13: 44197.229 | B13: ='N1'!AT13+'N2'!AT13+'N3'!AT13+'P2'!AT13+'A2'!AT13+'A3'!AR13 -> 21.559698
... A251: 44202.188 | B251: ='N1'!AT251+'N2'!AT251+'N3'!AT251+'P2'!AT251+'A2'!AT251+'A3'!AR251 -> 47.499466

Sheet N1
A1: supply_temp | B1: return_temp | C1: ct_conductivity | D1: ct_ph | E1: Bore | F1: CWRO | G1: BoilerBD | H1: BD | I1: scheme | J1: mu_conductivity | K1: mu_flow(PV) | L1: mu-flow(OV) | M1: m-saving(PV-OV) | N1: mu_ph | O1: cooling_tower_level | P1: relative_humidity | Q1: ambient_temp | R1: delta_temp | S1: wetBulb_temp | T1: approach_temp | U1: cond_coc | V1: ct_tds | W1: ct_ca | X1: ct_alk | Y1: ct_chloride | Z1: flow_cycle | AA1: sat_index | AB1: sta_index | AC1: perf_index | AD1: system_vol | AE1: rec_rate | AF1: evap_loss | AG1: drift_loss | AH1: blowdown_coc | AI1: hold_time_index | AJ1: dosing_residual | AK1: dosing_contact_time | AL1: dosing_density | AM1: dosing_continuous | AN1: dosing_initial | AO1: dosing_slug | AP1: currentOperatingCost | AQ1: newOperatingCost | AR1: updatedDateTime | AS1: Date and Time | AT1: =SUM(AT2:AT251) -> 2612.023 | AU1: Total Savings
A2: 20.76 | B2: 30.37 | C2: 5924.33 | D2: 7.61 | E2: [40.49, 62.44] | F2: [25.03, 5.46] | G2: [6.37, 6.37] | H2: [10.0, 12.38] | I2: 0 | J2: 906.05 | K2: =IF(E2=0,0, VALUE(MID(E2,2,FIND(",",E2)-2))+ VALUE(MID(F2,2,FIND(",",F2)-2))+ VALUE(MID(G2,2,FIND(",",G2)-2)) ) -> 71.89 | L2: =IF(E2=0,0, VALUE(MID(E2,FIND(",",E2)+1,FIND("]",E2)-FIND(",",E2)-1))+ VALUE(MID(F2,FIND(",",F2)+1,FIND("]",F2)-FIND(",",F2)-1))+ VALUE(MID(G2,FIND(",",G2)+1,FIND("]",G2)-FIND(",",G2)-1)) ) -> 74.27 | M2: =(K2-L2) -> -2.38 | N2: 7.3 | O2: 91.61 | P2: 59 | Q2: 21.1 | R2: 9.61 | S2: 15.87 | T2: 4.89 | U2: 6.54 | V2: 3791.57 | W2: 1118.63 | X2: 1256.11 | Y2: 782.42 | Z2: 5.81 | AA2: 1.63 | AB2: 4.35 | AC2: 66.28 | AD2: 490 | AE2: 4700 | AF2: 69.14 | AG2: 0.47 | AH2: 12.48 | AI2: 27.43 | AJ2: 60 | AK2: 9 | AL2: 9 | AM2: 0.83 | AN2: 294 | AO2: 301.43 | AP2: 449634.83 | AQ2: 253017.12 | AR2: 20230124-093759_8f3cf142-09ac-4146-806e-26f92db6205a | AT2: =(AP2-AQ2)/(365*24*2) -> 11.222472 | AU2: =SUM(AT2:AT251) -> 2612.023 | AV2: =250/48 -> 5.2083333
A3: 19.76 | B3: 29.44 | C3: 5732.92 | D3: 7.59 | E3: [52.3, 61.55] | F3: [24.99, 17.97] | G3: [6.14, 6.14] | H3: [10.0, 12.24] | I3: 0 | J3: 997.95 | K3: =IF(E3=0,0, VALUE(MID(E3,2,FIND(",",E3)-2))+ VALUE(MID(F3,2,FIND(",",F3)-2))+ VALUE(MID(G3,2,FIND(",",G3)-2)) ) -> 83.43 | L3: =IF(E3=0,0, VALUE(MID(E3,FIND(",",E3)+1,FIND("]",E3)-FIND(",",E3)-1))+ VALUE(MID(F3,FIND(",",F3)+1,FIND("]",F3)-FIND(",",F3)-1))+ VALUE(MID(G3,FIND(",",G3)+1,FIND("]",G3)-FIND(",",G3)-1)) ) -> 85.66 | M3: =(K3-L3) -> -2.23 | N3: 7.37 | O3: 92.04 | P3: 67 | Q3: 18.3 | R3: 9.68 | S3: 14.33 | T3: 5.42 | U3: 5.74 | V3: 3669.07 | W3: 1080.77 | X3: 1193.48 | Y3: 752.1 | Z3: 6.82 | AA3: 1.56 | AB3: 4.48 | AC3: 64.1 | AD3: 490 | AE3: 4700 | AF3: 69.63 | AG3: 0.47 | AH3: 14.68 | AI3: 27.75 | AJ3: 60 | AK3: 9 | AL3: 9 | AM3: 0.82 | AN3: 294 | AO3: 301.34 | AP3: 459321.39 | AQ3: 404056.38 | AR3: 20230124-093759_a884498a-9014-4d7b-93b0-1726eebac697 | AT3: =(AP3-AQ3)/(365*24*2) -> 3.1543955
A4: 21.42 | B4: 30.97 | C4: 5976.4 | D4: 7.6 | E4: [33.83, 55.48] | F4: [25.0, 4.34] | G4: [6.16, 6.16] | H4: [10.01, 11.0] | I4: 0 | J4: 843.47 | K4: =IF(E4=0,0, VALUE(MID(E4,2,FIND(",",E4)-2))+ VALUE(MID(F4,2,FIND(",",F4)-2))+ VALUE(MID(G4,2,FIND(",",G4)-2)) ) -> 64.99 | L4: =IF(E4=0,0, VALUE(MID(E4,FIND(",",E4)+1,FIND("]",E4)-FIND(",",E4)-1))+ VALUE(MID(F4,FIND(",",F4)+1,FIND("]",F4)-FIND(",",F4)-1))+ VALUE(MID(G4,FIND(",",G4)+1,FIND("]",G4)-FIND(",",G4)-1)) ) -> 65.98 | M4: =(K4-L4) -> -0.99 | N4: 7.24 | O4: 92.01 | P4: 63 | Q4: 21.3 | R4: 9.56 | S4: 16.58 | T4: 4.84 | U4: 7.09 | V4: 3824.9 | W4: 1129.37 | X4: 1281.78 | Y4: 792.27 | Z4: 5.91 | AA4: 1.64 | AB4: 4.31 | AC4: 66.37 | AD4: 490 | AE4: 4700 | AF4: 68.71 | AG4: 0.47 | AH4: 11.29 | AI4: 30.88 | AJ4: 60 | AK4: 9 | AL4: 9 | AM4: 0.73 | AN4: 294 | AO4: 300.6 | AP4: 443334.66 | AQ4: 218955.23 | AR4: 20230124-093759_cffc3147-744b-4994-ace0-e0882e8a1dd7 | AT4: =(AP4-AQ4)/(365*24*2) -> 12.807045
A5: 20.75 | B5: 30.47 | C5: 5878.94 | D5: 7.58 | E5: [40.9, 41.44] | F5: [24.94, 22.68] | G5: [6.16, 6.16] | H5: [9.99, 8.27] | I5: 0 | J5: 912.54 | K5: =IF(E5=0,0, VALUE(MID(E5,2,FIND(",",E5)-2))+ VALUE(MID(F5,2,FIND(",",F5)-2))+ VALUE(MID(G5,2,FIND(",",G5)-2)) ) -> 72 | L5: =IF(E5=0,0, VALUE(MID(E5,FIND(",",E5)+1,FIND("]",E5)-FIND(",",E5)-1))+ VALUE(MID(F5,FIND(",",F5)+1,FIND("]",F5)-FIND(",",F5)-1))+ VALUE(MID(G5,FIND(",",G5)+1,FIND("]",G5)-FIND(",",G5)-1)) ) -> 70.28 | M5: =(K5-L5) -> 1.72 | N5: 7.3 | O5: 91.46 | P5: 59 | Q5: 20 | R5: 9.72 | S5: 14.88 | T5: 5.87 | U5: 6.44 | V5: 3762.52 | W5: 1109.68 | X5: 1242.95 | Y5: 775.45 | Z5: 8.71 | AA5: 1.59 | AB5: 4.4 | AC5: 62.36 | AD5: 490 | AE5: 4700 | AF5: 69.91 | AG5: 0.47 | AH5: 12.85 | AI5: 41.07 | AJ5: 60 | AK5: 9 | AL5: 9 | AM5: 0.55 | AN5: 294 | AO5: 298.96 | AP5: 448674.97 | AQ5: 403895.05 | AR5: 20230124-093759_9f0a1368-5ec7-48f3-a1f7-b03589439cab | AT5: =(AP5-AQ5)/(365*24*2) -> 2.5559315
A6: 21.17 | B6: 30.7 | C6: 5916.9 | D6: 7.6 | E6: [13.37, 34.98] | F6: [24.98, 0.29] | G6: [6.29, 6.29] | H6: [10.0, 6.93] | I6: 0 | J6: 523.08 | K6: =IF(E6=0,0, VALUE(MID(E6,2,FIND(",",E6)-2))+ VALUE(MID(F6,2,FIND(",",F6)-2))+ VALUE(MID(G6,2,FIND(",",G6)-2)) ) -> 44.64 | L6: =IF(E6=0,0, VALUE(MID(E6,FIND(",",E6)+1,FIND("]",E6)-FIND(",",E6)-1))+ VALUE(MID(F6,FIND(",",F6)+1,FIND("]",F6)-FIND(",",F6)-1))+ VALUE(MID(G6,FIND(",",G6)+1,FIND("]",G6)-FIND(",",G6)-1)) ) -> 41.56 | M6: =(K6-L6) -> 3.08 | N6: 6.99 | O6: 91.91 | P6: 85 | Q6: 18.9 | R6: 9.53 | S6: 17.08 | T6: 4.09 | U6: 11.31 | V6: 3786.82 | W6: 1129.14 | X6: 1419.45 | Y6: 817.61 | Z6: 6.44 | AA6: 1.69 | AB6: 4.23 | AC6: 69.99 | AD6: 490 | AE6: 4700 | AF6: 68.56 | AG6: 0.47 | AH6: 6.65 | AI6: 49.02 | AJ6: 60 | AK6: 9 | AL6: 9 | AM6: 0.46 | AN6: 294 | AO6: 298.16 | AP6: 425136.63 | AQ6: 110138.14 | AR6: 20230124-093759_e697bf3c-588b-4d89-9b61-67d892014333 | AT6: =(AP6-AQ6)/(365*24*2) -> 17.979366
A7: 20.21 | B7: 29.67 | C7: 5811.62 | D7: 7.6 | E7: [52.92, 52.92] | F7: [24.99, 24.99] | G7: [6.19, 6.19] | H7: [10.0, 10.0] | I7: 0 | J7: 1001.5 | K7: =IF(E7=0,0, VALUE(MID(E7,2,FIND(",",E7)-2))+ VALUE(MID(F7,2,FIND(",",F7)-2))+ VALUE(MID(G7,2,FIND(",",G7)-2)) ) -> 84.1 | L7: =IF(E7=0,0, VALUE(MID(E7,FIND(",",E7)+1,FIND("]",E7)-FIND(",",E7)-1))+ VALUE(MID(F7,FIND(",",F7)+1,FIND("]",F7)-FIND(",",F7)-1))+ VALUE(MID(G7,FIND(",",G7)+1,FIND("]",G7)-FIND(",",G7)-1)) ) -> 84.1 | M7: =(K7-L7) -> 0 | N7: 7.37 | O7: 92.17 | P7: 64 | Q7: 19.7 | R7: 9.46 | S7: 15.25 | T7: 4.96 | U7: 5.8 | V7: 3719.44 | W7: 1095.61 | X7: 1209.55 | Y7: 762.4 | Z7: 8.41 | AA7: 1.59 | AB7: 4.43 | AC7: 65.59 | AD7: 490 | AE7: 4700 | AF7: 68.01 | AG7: 0.47 | AH7: 14.16 | AI7: 33.96 | AJ7: 60 | AK7: 9 | AL7: 9 | AM7: 0.67 | AN7: 294 | AO7: 300 | AP7: 459901.71 | AQ7: 459901.71 | AR7: 20230124-093759_5bf3c0ad-e364-4209-aee7-a3fb00439d48 | AT7: =(AP7-AQ7)/(365*24*2) -> 0
A8: 19.46 | B8: 29.22 | C8: 5725.12 | D8: 7.6 | E8: [38.39, 60.08] | F8: [25.07, 5.28] | G8: [6.1, 6.1] | H8: [10.01, 11.91] | I8: 0 | J8: 888.87 | K8: =IF(E8=0,0, VALUE(MID(E8,2,FIND(",",E8)-2))+ VALUE(MID(F8,2,FIND(",",F8)-2))+ VALUE(MID(G8,2,FIND(",",G8)-2)) ) -> 69.56 | L8: =IF(E8=0,0, VALUE(MID(E8,FIND(",",E8)+1,FIND("]",E8)-FIND(",",E8)-1))+ VALUE(MID(F8,FIND(",",F8)+1,FIND("]",F8)-FIND(",",F8)-1))+ VALUE(MID(G8,FIND(",",G8)+1,FIND("]",G8)-FIND(",",G8)-1)) ) -> 71.46 | M8: =(K8-L8) -> -1.9 | N8: 7.28 | O8: 91.76 | P8: 66 | Q8: 18.2 | R8: 9.76 | S8: 14.12 | T8: 5.34 | U8: 6.44 | V8: 3664.08 | W8: 1080.93 | X8: 1215.21 | Y8: 756.11 | Z8: 5.84 | AA8: 1.56 | AB8: 4.47 | AC8: 64.63 | AD8: 490 | AE8: 4700 | AF8: 70.19 | AG8: 0.47 | AH8: 12.9 | AI8: 28.51 | AJ8: 60 | AK8: 9 | AL8: 9 | AM8: 0.79 | AN8: 294 | AO8: 301.15 | AP8: 448105.4 | AQ8: 243772.76 | AR8: 20230124-093759_f9e7fcbc-77c4-4dc7-8ef4-49ac28693c79 | AT8: =(AP8-AQ8)/(365*24*2) -> 11.662822
A9: 20.4 | B9: 29.86 | C9: 5787.74 | D9: 7.6 | E9: [36.96, 53.36] | F9: [25.08, 9.26] | G9: [6.22, 6.22] | H9: [10.01, 10.59] | I9: 0 | J9: 874.01 | K9: =IF(E9=0,0, VALUE(MID(E9,2,FIND(",",E9)-2))+ VALUE(MID(F9,2,FIND(",",F9)-2))+ VALUE(MID(G9,2,FIND(",",G9)-2)) ) -> 68.26 | L9: =IF(E9=0,0, VALUE(MID(E9,FIND(",",E9)+1,FIND("]",E9)-FIND(",",E9)-1))+ VALUE(MID(F9,FIND(",",F9)+1,FIND("]",F9)-FIND(",",F9)-1))+ VALUE(MID(G9,FIND(",",G9)+1,FIND("]",G9)-FIND(",",G9)-1)) ) -> 68.84 | M9: =(K9-L9) -> -0.58 | N9: 7.27 | O9: 91.91 | P9: 73 | Q9: 18.4 | R9: 9.47 | S9: 15.15 | T9: 5.24 | U9: 6.62 | V9: 3704.15 | W9: 1093.2 | X9: 1233.58 | Y9: 765.62 | Z9: 6.44 | AA9: 1.59 | AB9: 4.41 | AC9: 64.35 | AD9: 490 | AE9: 4700 | AF9: 68.06 | AG9: 0.47 | AH9: 12.11 | AI9: 32.06 | AJ9: 60 | AK9: 9 | AL9: 9 | AM9: 0.71 | AN9: 294 | AO9: 300.36 | AP9: 447109.41 | AQ9: 273378.74 | AR9: 20230124-093759_73ba74f0-c493-4a9d-a540-f7430c20f7bd | AT9: =(AP9-AQ9)/(365*24*2) -> 9.9161341
A10: 20.91 | B10: 30.52 | C10: 5912.7 | D10: 7.6 | E10: [45.76, 75.11] | F10: [24.92, 0.45] | G10: [6.24, 6.24] | H10: [10.0, 14.87] | I10: 0 | J10: 951.86 | K10: =IF(E10=0,0, VALUE(MID(E10,2,FIND(",",E10)-2))+ VALUE(MID(F10,2,FIND(",",F10)-2))+ VALUE(MID(G10,2,FIND(",",G10)-2)) ) -> 76.92 | L10: =IF(E10=0,0, VALUE(MID(E10,FIND(",",E10)+1,FIND("]",E10)-FIND(",",E10)-1))+ VALUE(MID(F10,FIND(",",F10)+1,FIND("]",F10)-FIND(",",F10)-1))+ VALUE(MID(G10,FIND(",",G10)+1,FIND("]",G10)-FIND(",",G10)-1)) ) -> 81.8 | M10: =(K10-L10) -> -4.88 | N10: 7.33 | O10: 91.99 | P10: 58 | Q10: 21 | R10: 9.61 | S10: 15.64 | T10: 5.27 | U10: 6.21 | V10: 3784.13 | W10: 1115.51 | X10: 1241.77 | Y10: 778.17 | Z10: 5.17 | AA10: 1.61 | AB10: 4.37 | AC10: 64.59 | AD10: 490 | AE10: 4700 | AF10: 69.08 | AG10: 0.47 | AH10: 13.25 | AI10: 22.83 | AJ10: 60 | AK10: 9 | AL10: 9 | AM10: 0.99 | AN10: 294 | AO10: 302.92 | AP10: 452729.93 | AQ10: 227913.5 | AR10: 20230124-093759_a87f9bba-c063-48b0-9805-748c97392c9e | AT10: =(AP10-AQ10)/(365*24*2) -> 12.831988
A11: 19.87 | B11: 29.6 | C11: 5759.2 | D11: 7.59 | E11: [28.69, 50.25] | F11: [24.95, 3.36] | G11: [6.15, 6.15] | H11: [10.0, 9.96] | I11: 0 | J11: 784.45 | K11: =IF(E11=0,0, VALUE(MID(E11,2,FIND(",",E11)-2))+ VALUE(MID(F11,2,FIND(",",F11)-2))+ VALUE(MID(G11,2,FIND(",",G11)-2)) ) -> 59.79 | L11: =IF(E11=0,0, VALUE(MID(E11,FIND(",",E11)+1,FIND("]",E11)-FIND(",",E11)-1))+ VALUE(MID(F11,FIND(",",F11)+1,FIND("]",F11)-FIND(",",F11)-1))+ VALUE(MID(G11,FIND(",",G11)+1,FIND("]",G11)-FIND(",",G11)-1)) ) -> 59.76 | M11: =(K11-L11) -> 0.03 | N11: 7.19 | O11: 91.87 | P11: 72 | Q11: 18.2 | R11: 9.73 | S11: 14.84 | T11: 5.03 | U11: 7.34 | V11: 3685.89 | W11: 1089.57 | X11: 1252.65 | Y11: 767.28 | Z11: 6 | AA11: 1.59 | AB11: 4.42 | AC11: 65.95 | AD11: 490 | AE11: 4700 | AF11: 70 | AG11: 0.47 | AH11: 11.04 | AI11: 34.1 | AJ11: 60 | AK11: 9 | AL11: 9 | AM11: 0.66 | AN11: 294 | AO11: 299.98 | AP11: 438166.94 | AQ11: 191761.92 | AR11: 20230124-093759_27d58fd8-c9d7-41fe-ae29-27a121326add | AT11: =(AP11-AQ11)/(365*24*2) -> 14.064213
A12: 20.7 | B12: 30.3 | C12: 5882.47 | D12: 7.6 | E12: [59.11, 90.12] | F12: [24.99, 1.84] | G12: [6.21, 6.21] | H12: [10.0, 17.85] | I12: 0 | J12: 1038.24 | K12: =IF(E12=0,0, VALUE(MID(E12,2,FIND(",",E12)-2))+ VALUE(MID(F12,2,FIND(",",F12)-2))+ VALUE(MID(G12,2,FIND(",",G12)-2)) ) -> 90.31 | L12: =IF(E12=0,0, VALUE(MID(E12,FIND(",",E12)+1,FIND("]",E12)-FIND(",",E12)-1))+ VALUE(MID(F12,FIND(",",F12)+1,FIND("]",F12)-FIND(",",F12)-1))+ VALUE(MID(G12,FIND(",",G12)+1,FIND("]",G12)-FIND(",",G12)-1)) ) -> 98.17 | M12: =(K12-L12) -> -7.86 | N12: 7.4 | O12: 91.8 | P12: 59 | Q12: 21.2 | R12: 9.6 | S12: 15.95 | T12: 4.75 | U12: 5.67 | V12: 3764.78 | W12: 1108.47 | X12: 1217.32 | Y12: 770.18 | Z12: 5.06 | AA12: 1.6 | AB12: 4.4 | AC12: 66.9 | AD12: 490 | AE12: 4700 | AF12: 69.01 | AG12: 0.47 | AH12: 14.79 | AI12: 19.03 | AJ12: 60 | AK12: 9 | AL12: 9 | AM12: 1.19 | AN12: 294 | AO12: 304.71 | AP12: 465393.42 | AQ12: 288290.62 | AR12: 20230124-093759_bf97e8b9-d8f1-4edf-bea6-381a9adeadb3 | AT12: =(AP12-AQ12)/(365*24*2) -> 10.108607
A13: 21 | B13: 30.55 | C13: 5924.62 | D13: 7.61 | E13: [39.93, 68.53] | F13: [25.12, 0.08] | G13: [6.02, 6.02] | H13: [10.0, 13.57] | I13: 0 | J13: 903.02 | K13: =IF(E13=0,0, VALUE(MID(E13,2,FIND(",",E13)-2))+ VALUE(MID(F13,2,FIND(",",F13)-2))+ VALUE(MID(G13,2,FIND(",",G13)-2)) ) -> 71.07 | L13: =IF(E13=0,0, VALUE(MID(E13,FIND(",",E13)+1,FIND("]",E13)-FIND(",",E13)-1))+ VALUE(MID(F13,FIND(",",F13)+1,FIND("]",F13)-FIND(",",F13)-1))+ VALUE(MID(G13,FIND(",",G13)+1,FIND("]",G13)-FIND(",",G13)-1)) ) -> 74.63 | M13: =(K13-L13) -> -3.56 | N13: 7.29 | O13: 92.14 | P13: 62 | Q13: 21.1 | R13: 9.55 | S13: 16.26 | T13: 4.74 | U13: 6.56 | V13: 3791.76 | W13: 1118.2 | X13: 1253 | Y13: 781.36 | Z13: 5.24 | AA13: 1.63 | AB13: 4.34 | AC13: 66.83 | AD13: 490 | AE13: 4700 | AF13: 68.67 | AG13: 0.47 | AH13: 12.35 | AI13: 25.03 | AJ13: 60 | AK13: 9 | AL13: 9 | AM13: 0.9 | AN13: 294 | AO13: 302.14 | AP13: 449916.72 | AQ13: 204225.54 | AR13: 20230124-093759_5e9220f6-d8db-462c-ab1f-046510eb9f5f | AT13: =(AP13-AQ13)/(365*24*2) -> 14.023469
A14: 20.13 | B14: 29.76 | C14: 5843.46 | D14: 7.6 | E14: [53.1, 53.1] | F14: [25.04, 25.04] | G14: [6.39, 6.39] | H14: [10.0, 10.0] | I14: 0 | J14: 1000.48 | K14: =IF(E14=0,0, VALUE(MID(E14,2,FIND(",",E14)-2))+ VALUE(MID(F14,2,FIND(",",F14)-2))+ VALUE(MID(G14,2,FIND(",",G14)-2)) ) -> 84.53 | L14: =IF(E14=0,0, VALUE(MID(E14,FIND(",",E14)+1,FIND("]",E14)-FIND(",",E14)-1))+ VALUE(MID(F14,FIND(",",F14)+1,FIND("]",F14)-FIND(",",F14)-1))+ VALUE(MID(G14,FIND(",",G14)+1,FIND("]",G14)-FIND(",",G14)-1)) ) -> 84.53 | M14: =(K14-L14) -> 0 | N14: 7.37 | O14: 91.64 | P14: 55 | Q14: 20.3 | R14: 9.63 | S14: 14.63 | T14: 5.5 | U14: 5.84 | V14: 3739.81 | W14: 1101.83 | X14: 1217.87 | Y14: 767.1 | Z14: 8.45 | AA14: 1.59 | AB14: 4.42 | AC14: 63.65 | AD14: 490 | AE14: 4700 | AF14: 69.28 | AG14: 0.47 | AH14: 14.31 | AI14: 33.95 | AJ14: 60 | AK14: 9 | AL14: 9 | AM14: 0.67 | AN14: 294 | AO14: 300 | AP14: 460795.85 | AQ14: 460795.85 | AR14: 20230124-093759_c3d9a479-9ca6-4a54-af09-f91d19f3bb51 | AT14: =(AP14-AQ14)/(365*24*2) -> 0
... A69: 16.8 | B69: 27.47 | C69: 5515.91 | D69: 7.6 | E69: [13.44, 42.75] | F69: [25.07, 1.06] | G69: [7.0, 7.0] | H69: [3.17, 8.47] | I69: 0 | J69: 520.27 | K69: =IF(E69=0,0, VALUE(MID(E69,2,FIND(",",E69)-2))+ VALUE(MID(F69,2,FIND(",",F69)-2))+ VALUE(MID(G69,2,FIND(",",G69)-2)) ) -> 45.51 | L69: =IF(E69=0,0, VALUE(MID(E69,FIND(",",E69)+1,FIND("]",E69)-FIND(",",E69)-1))+ VALUE(MID(F69,FIND(",",F69)+1,FIND("]",F69)-FIND(",",F69)-1))+ VALUE(MID(G69,FIND(",",G69)+1,FIND("]",G69)-FIND(",",G69)-1)) ) -> 50.81 | M69: =(K69-L69) -> -5.3 | N69: 7 | O69: 86.3 | P69: 82 | Q69: 13.2 | R69: 10.67 | S69: 11.21 | T69: 5.59 | U69: 10.6 | V69: 3530.18 | W69: 1055.25 | X69: 1343.35 | Y69: 768.44 | Z69: 5.37 | AA69: 1.54 | AB69: 4.51 | AC69: 65.63 | AD69: 490 | AE69: 4700 | AF69: 76.71 | AG69: 0.47 | AH69: 7.99 | AI69: 40.1 | AJ69: 60 | AK69: 9 | AL69: 9 | AM69: 0.56 | AN69: 294 | AO69: 299.08 | AP69: 357511.29 | AQ69: 142573.01 | AR69: 20230124-095412_edde0de5-8c58-4be8-8a07-4923dacb28e2 | AT69: =(AP69-AQ69)/(365*24*2) -> 12.268167
A70: 0 | B70: 0 | C70: 0 | D70: 0 | E70: 0 | F70: 0 | G70: 0 | H70: 0 | I70: 0 | J70: 0 | K70: =IF(E70=0,0, VALUE(MID(E70,2,FIND(",",E70)-2))+ VALUE(MID(F70,2,FIND(",",F70)-2))+ VALUE(MID(G70,2,FIND(",",G70)-2)) ) -> 0 | L70: =IF(E70=0,0, VALUE(MID(E70,FIND(",",E70)+1,FIND("]",E70)-FIND(",",E70)-1))+ VALUE(MID(F70,FIND(",",F70)+1,FIND("]",F70)-FIND(",",F70)-1))+ VALUE(MID(G70,FIND(",",G70)+1,FIND("]",G70)-FIND(",",G70)-1)) ) -> 0 | M70: =(K70-L70) -> 0 | N70: 0 | O70: 0 | P70: 0 | Q70: 0 | R70: 0 | S70: 0 | T70: 0 | U70: 0 | V70: 0 | W70: 0 | X70: 0 | Y70: 0 | Z70: 0 | AA70: 0 | AB70: 0 | AC70: 0 | AD70: 0 | AE70: 0 | AF70: 0 | AG70: 0 | AH70: 0 | AI70: 0 | AJ70: 0 | AK70: 0 | AL70: 0 | AM70: 0 | AN70: 0 | AO70: 0 | AP70: 0 | AQ70: 0 | AR70: 0 | AT70: =(AP70-AQ70)/(365*24*2) -> 0
A71: 15.11 | B71: 27.04 | C71: 5457.65 | D71: 7.58 | E71: [15.55, 43.68] | F71: [25.01, 1.8] | G71: [10.77, 10.77] | H71: [3.73, 8.65] | I71: 0 | J71: 546.51 | K71: =IF(E71=0,0, VALUE(MID(E71,2,FIND(",",E71)-2))+ VALUE(MID(F71,2,FIND(",",F71)-2))+ VALUE(MID(G71,2,FIND(",",G71)-2)) ) -> 51.33 | L71: =IF(E71=0,0, VALUE(MID(E71,FIND(",",E71)+1,FIND("]",E71)-FIND(",",E71)-1))+ VALUE(MID(F71,FIND(",",F71)+1,FIND("]",F71)-FIND(",",F71)-1))+ VALUE(MID(G71,FIND(",",G71)+1,FIND("]",G71)-FIND(",",G71)-1)) ) -> 56.25 | M71: =(K71-L71) -> -4.92 | N71: 7.11 | O71: 85.14 | P71: 84 | Q71: 11.3 | R71: 11.93 | S71: 9.58 | T71: 5.53 | U71: 9.99 | V71: 3492.9 | W71: 1053.94 | X71: 1392.41 | Y71: 782.35 | Z71: 5.93 | AA71: 1.51 | AB71: 4.56 | AC71: 68.35 | AD71: 490 | AE71: 4700 | AF71: 85.81 | AG71: 0.47 | AH71: 9.55 | AI71: 39.24 | AJ71: 60 | AK71: 9 | AL71: 9 | AM71: 0.58 | AN71: 294 | AO71: 299.19 | AP71: 367629.54 | AQ71: 157686.56 | AR71: 20230124-095412_f0eeab57-d398-4f27-8012-f829bc365b30 | AT71: =(AP71-AQ71)/(365*24*2) -> 11.983047
A72: 15.29 | B72: 27.38 | C72: 5476.2 | D72: 7.59 | E72: [11.04, 33.26] | F72: [25.03, 2.0] | G72: [10.88, 10.88] | H72: [7.4, 6.59] | I72: 0 | J72: 450.38 | K72: =IF(E72=0,0, VALUE(MID(E72,2,FIND(",",E72)-2))+ VALUE(MID(F72,2,FIND(",",F72)-2))+ VALUE(MID(G72,2,FIND(",",G72)-2)) ) -> 46.95 | L72: =IF(E72=0,0, VALUE(MID(E72,FIND(",",E72)+1,FIND("]",E72)-FIND(",",E72)-1))+ VALUE(MID(F72,FIND(",",F72)+1,FIND("]",F72)-FIND(",",F72)-1))+ VALUE(MID(G72,FIND(",",G72)+1,FIND("]",G72)-FIND(",",G72)-1)) ) -> 46.14 | M72: =(K72-L72) -> 0.81 | N72: 7.05 | O72: 85.41 | P72: 89 | Q72: 10.6 | R72: 12.09 | S72: 9.41 | T72: 5.88 | U72: 12.16 | V72: 3504.77 | W72: 1067.75 | X72: 1506.49 | Y72: 812.6 | Z72: 7.12 | AA72: 1.57 | AB72: 4.46 | AC72: 67.27 | AD72: 490 | AE72: 4700 | AF72: 86.93 | AG72: 0.47 | AH72: 7.79 | AI72: 51.52 | AJ72: 60 | AK72: 9 | AL72: 9 | AM72: 0.44 | AN72: 294 | AO72: 297.95 | AP72: 401309.5 | AQ72: 130154.35 | AR72: 20230124-095412_760e8553-f762-4cd3-882e-86b87a1cbe9c | AT72: =(AP72-AQ72)/(365*24*2) -> 15.476892
A73: 15.96 | B73: 27.61 | C73: 5510.67 | D73: 7.57 | E73: [30.71, 58.29] | F73: [25.03, 0.54] | G73: [10.42, 10.42] | H73: [8.46, 11.54] | I73: 0 | J73: 775.31 | K73: =IF(E73=0,0, VALUE(MID(E73,2,FIND(",",E73)-2))+ VALUE(MID(F73,2,FIND(",",F73)-2))+ VALUE(MID(G73,2,FIND(",",G73)-2)) ) -> 66.16 | L73: =IF(E73=0,0, VALUE(MID(E73,FIND(",",E73)+1,FIND("]",E73)-FIND(",",E73)-1))+ VALUE(MID(F73,FIND(",",F73)+1,FIND("]",F73)-FIND(",",F73)-1))+ VALUE(MID(G73,FIND(",",G73)+1,FIND("]",G73)-FIND(",",G73)-1)) ) -> 69.25 | M73: =(K73-L73) -> -3.09 | N73: 7.26 | O73: 84.25 | P73: 88 | Q73: 11 | R73: 11.66 | S73: 9.7 | T73: 6.26 | U73: 7.11 | V73: 3526.83 | W73: 1049.91 | X73: 1253.41 | Y73: 751.45 | Z73: 5.73 | AA73: 1.47 | AB73: 4.63 | AC73: 65.07 | AD73: 490 | AE73: 4700 | AF73: 83.82 | AG73: 0.47 | AH73: 13.72 | AI73: 29.42 | AJ73: 60 | AK73: 9 | AL73: 9 | AM73: 0.77 | AN73: 294 | AO73: 300.93 | AP73: 429016.27 | AQ73: 184134.86 | AR73: 20230124-095412_66051ab0-4f10-4816-be11-b7e756ec991b | AT73: =(AP73-AQ73)/(365*24*2) -> 13.977249
A74: 16.78 | B74: 28.32 | C74: 5506.73 | D74: 7.59 | E74: [29.85, 60.79] | F74: [24.98, 0.39] | G74: [11.05, 11.05] | H74: [5.68, 12.04] | I74: 0 | J74: 761.33 | K74: =IF(E74=0,0, VALUE(MID(E74,2,FIND(",",E74)-2))+ VALUE(MID(F74,2,FIND(",",F74)-2))+ VALUE(MID(G74,2,FIND(",",G74)-2)) ) -> 65.88 | L74: =IF(E74=0,0, VALUE(MID(E74,FIND(",",E74)+1,FIND("]",E74)-FIND(",",E74)-1))+ VALUE(MID(F74,FIND(",",F74)+1,FIND("]",F74)-FIND(",",F74)-1))+ VALUE(MID(G74,FIND(",",G74)+1,FIND("]",G74)-FIND(",",G74)-1)) ) -> 72.23 | M74: =(K74-L74) -> -6.35 | N74: 7.26 | O74: 86.23 | P74: 85 | Q74: 12.7 | R74: 11.54 | S74: 11.05 | T74: 5.74 | U74: 7.23 | V74: 3524.31 | W74: 1050.73 | X74: 1266.08 | Y74: 754.81 | Z74: 5.47 | AA74: 1.51 | AB74: 4.57 | AC74: 66.79 | AD74: 490 | AE74: 4700 | AF74: 82.96 | AG74: 0.47 | AH74: 13.31 | AI74: 28.21 | AJ74: 60 | AK74: 9 | AL74: 9 | AM74: 0.8 | AN74: 294 | AO74: 301.22 | AP74: 399919.2 | AQ74: 190040.74 | AR74: 20230124-095412_6d86d795-4c62-4be9-8b86-c68973b2885f | AT74: =(AP74-AQ74)/(365*24*2) -> 11.979364
A75: 16.79 | B75: 28.15 | C75: 5531.31 | D75: 7.59 | E75: [20.09, 46.44] | F75: [24.98, 2.82] | G75: [10.56, 10.56] | H75: [5.01, 9.2] | I75: 0 | J75: 628.74 | K75: =IF(E75=0,0, VALUE(MID(E75,2,FIND(",",E75)-2))+ VALUE(MID(F75,2,FIND(",",F75)-2))+ VALUE(MID(G75,2,FIND(",",G75)-2)) ) -> 55.63 | L75: =IF(E75=0,0, VALUE(MID(E75,FIND(",",E75)+1,FIND("]",E75)-FIND(",",E75)-1))+ VALUE(MID(F75,FIND(",",F75)+1,FIND("]",F75)-FIND(",",F75)-1))+ VALUE(MID(G75,FIND(",",G75)+1,FIND("]",G75)-FIND(",",G75)-1)) ) -> 59.82 | M75: =(K75-L75) -> -4.19 | N75: 7.16 | O75: 85.65 | P75: 84 | Q75: 13 | R75: 11.36 | S75: 11.23 | T75: 5.55 | U75: 8.8 | V75: 3540.04 | W75: 1061.61 | X75: 1341.86 | Y75: 775.31 | Z75: 6.04 | AA75: 1.55 | AB75: 4.5 | AC75: 67.17 | AD75: 490 | AE75: 4700 | AF75: 81.7 | AG75: 0.47 | AH75: 10.48 | AI75: 36.9 | AJ75: 60 | AK75: 9 | AL75: 9 | AM75: 0.61 | AN75: 294 | AO75: 299.52 | AP75: 384192.69 | AQ75: 178030.48 | AR75: 20230124-095412_5f75f2f2-b1d5-43d3-bd74-a9645dcc7ebc | AT75: =(AP75-AQ75)/(365*24*2) -> 11.767249
A76: 16.34 | B76: 27.97 | C76: 5514.27 | D76: 7.59 | E76: [6.12, 30.19] | F76: [25.02, 0.51] | G76: [11.16, 11.16] | H76: [6.42, 5.98] | I76: 0 | J76: 322.8 | K76: =IF(E76=0,0, VALUE(MID(E76,2,FIND(",",E76)-2))+ VALUE(MID(F76,2,FIND(",",F76)-2))+ VALUE(MID(G76,2,FIND(",",G76)-2)) ) -> 42.3 | L76: =IF(E76=0,0, VALUE(MID(E76,FIND(",",E76)+1,FIND("]",E76)-FIND(",",E76)-1))+ VALUE(MID(F76,FIND(",",F76)+1,FIND("]",F76)-FIND(",",F76)-1))+ VALUE(MID(G76,FIND(",",G76)+1,FIND("]",G76)-FIND(",",G76)-1)) ) -> 41.86 | M76: =(K76-L76) -> 0.44 | N76: 6.97 | O76: 85.97 | P76: 87 | Q76: 12 | R76: 11.63 | S76: 10.58 | T76: 5.77 | U76: 17.08 | V76: 3529.13 | W76: 1099.29 | X76: 1771.6 | Y76: 882.97 | Z76: 7.07 | AA76: 1.67 | AB76: 4.25 | AC76: 66.85 | AD76: 490 | AE76: 4700 | AF76: 83.6 | AG76: 0.47 | AH76: 5.2 | AI76: 56.78 | AJ76: 60 | AK76: 9 | AL76: 9 | AM76: 0.4 | AN76: 294 | AO76: 297.59 | AP76: 387260.62 | AQ76: 103215.17 | AR76: 20230124-095412_410d9d35-a83f-4db4-a61d-9950514dd89b | AT76: =(AP76-AQ76)/(365*24*2) -> 16.21264
A77: 15.06 | B77: 27.21 | C77: 5477.51 | D77: 7.59 | E77: [6.5, 30.78] | F77: [24.98, 0.24] | G77: [11.64, 11.64] | H77: [6.56, 6.09] | I77: 0 | J77: 333.42 | K77: =IF(E77=0,0, VALUE(MID(E77,2,FIND(",",E77)-2))+ VALUE(MID(F77,2,FIND(",",F77)-2))+ VALUE(MID(G77,2,FIND(",",G77)-2)) ) -> 43.12 | L77: =IF(E77=0,0, VALUE(MID(E77,FIND(",",E77)+1,FIND("]",E77)-FIND(",",E77)-1))+ VALUE(MID(F77,FIND(",",F77)+1,FIND("]",F77)-FIND(",",F77)-1))+ VALUE(MID(G77,FIND(",",G77)+1,FIND("]",G77)-FIND(",",G77)-1)) ) -> 42.66 | M77: =(K77-L77) -> 0.46 | N77: 6.99 | O77: 85.18 | P77: 89 | Q77: 10.5 | R77: 12.16 | S77: 9.31 | T77: 5.74 | U77: 16.43 | V77: 3505.61 | W77: 1092 | X77: 1751.19 | Y77: 876.22 | Z77: 7.08 | AA77: 1.64 | AB77: 4.31 | AC77: 67.91 | AD77: 490 | AE77: 4700 | AF77: 87.42 | AG77: 0.47 | AH77: 5.67 | AI77: 55.72 | AJ77: 60 | AK77: 9 | AL77: 9 | AM77: 0.41 | AN77: 294 | AO77: 297.66 | AP77: 388921.79 | AQ77: 102082.25 | AR77: 20230124-095412_19632414-a9ba-40f2-97b2-196c38c7ce9a | AT77: =(AP77-AQ77)/(365*24*2) -> 16.37212
A78: 15.05 | B78: 27.08 | C78: 5481.09 | D78: 7.61 | E78: [2.55, 24.93] | F78: [24.95, 1.67] | G78: [10.46, 10.46] | H78: [5.84, 4.94] | I78: 0 | J78: 209.24 | K78: =IF(E78=0,0, VALUE(MID(E78,2,FIND(",",E78)-2))+ VALUE(MID(F78,2,FIND(",",F78)-2))+ VALUE(MID(G78,2,FIND(",",G78)-2)) ) -> 37.96 | L78: =IF(E78=0,0, VALUE(MID(E78,FIND(",",E78)+1,FIND("]",E78)-FIND(",",E78)-1))+ VALUE(MID(F78,FIND(",",F78)+1,FIND("]",F78)-FIND(",",F78)-1))+ VALUE(MID(G78,FIND(",",G78)+1,FIND("]",G78)-FIND(",",G78)-1)) ) -> 37.06 | M78: =(K78-L78) -> 0.9 | N78: 6.87 | O78: 84.66 | P78: 88 | Q78: 10.4 | R78: 12.03 | S78: 9.11 | T78: 5.94 | U78: 26.2 | V78: 3507.9 | W78: 1130.34 | X78: 2185.65 | Y78: 981.63 | Z78: 7.68 | AA78: 1.76 | AB78: 4.08 | AC78: 66.97 | AD78: 490 | AE78: 4700 | AF78: 86.52 | AG78: 0.47 | AH78: 3.43 | AI78: 68.72 | AJ78: 60 | AK78: 9 | AL78: 9 | AM78: 0.33 | AN78: 294 | AO78: 296.96 | AP78: 376641.2 | AQ78: 101713.02 | AR78: 20230124-095412_7c85fcc3-d674-4e42-b6b7-633e0364bef1 | AT78: =(AP78-AQ78)/(365*24*2) -> 15.692248
A79: 16.11 | B79: 27.66 | C79: 5486.08 | D79: 7.61 | E79: [17.18, 41.2] | F79: [24.97, 0.92] | G79: [10.92, 10.92] | H79: [8.2, 8.16] | I79: 0 | J79: 576.69 | K79: =IF(E79=0,0, VALUE(MID(E79,2,FIND(",",E79)-2))+ VALUE(MID(F79,2,FIND(",",F79)-2))+ VALUE(MID(G79,2,FIND(",",G79)-2)) ) -> 53.07 | L79: =IF(E79=0,0, VALUE(MID(E79,FIND(",",E79)+1,FIND("]",E79)-FIND(",",E79)-1))+ VALUE(MID(F79,FIND(",",F79)+1,FIND("]",F79)-FIND(",",F79)-1))+ VALUE(MID(G79,FIND(",",G79)+1,FIND("]",G79)-FIND(",",G79)-1)) ) -> 53.04 | M79: =(K79-L79) -> 0.03 | N79: 7.14 | O79: 85.49 | P79: 88 | Q79: 10.8 | R79: 11.54 | S79: 9.5 | T79: 6.61 | U79: 9.51 | V79: 3511.09 | W79: 1057.41 | X79: 1376.32 | Y79: 780.78 | Z79: 6.5 | AA79: 1.56 | AB79: 4.49 | AC79: 63.6 | AD79: 490 | AE79: 4700 | AF79: 83.02 | AG79: 0.47 | AH79: 9.75 | AI79: 41.62 | AJ79: 60 | AK79: 9 | AL79: 9 | AM79: 0.54 | AN79: 294 | AO79: 298.9 | AP79: 414183.29 | AQ79: 139869.45 | AR79: 20230124-095412_0faf45c1-7ce5-4c18-91ae-97dd0d48a455 | AT79: =(AP79-AQ79)/(365*24*2) -> 15.657183
A80: 16.75 | B80: 27.69 | C80: 5523.75 | D80: 7.6 | E80: [14.0, 40.06] | F80: [24.98, 3.01] | G80: [8.55, 8.55] | H80: [3.84, 7.94] | I80: 0 | J80: 526.03 | K80: =IF(E80=0,0, VALUE(MID(E80,2,FIND(",",E80)-2))+ VALUE(MID(F80,2,FIND(",",F80)-2))+ VALUE(MID(G80,2,FIND(",",G80)-2)) ) -> 47.53 | L80: =IF(E80=0,0, VALUE(MID(E80,FIND(",",E80)+1,FIND("]",E80)-FIND(",",E80)-1))+ VALUE(MID(F80,FIND(",",F80)+1,FIND("]",F80)-FIND(",",F80)-1))+ VALUE(MID(G80,FIND(",",G80)+1,FIND("]",G80)-FIND(",",G80)-1)) ) -> 51.62 | M80: =(K80-L80) -> -4.09 | N80: 7.05 | O80: 86.03 | P80: 83 | Q80: 13.1 | R80: 10.94 | S80: 11.22 | T80: 5.52 | U80: 10.5 | V80: 3535.2 | W80: 1061.73 | X80: 1379.56 | Y80: 780.93 | Z80: 5.98 | AA80: 1.56 | AB80: 4.48 | AC80: 66.45 | AD80: 490 | AE80: 4700 | AF80: 78.69 | AG80: 0.47 | AH80: 8.28 | AI80: 42.76 | AJ80: 60 | AK80: 9 | AL80: 9 | AM80: 0.53 | AN80: 294 | AO80: 298.76 | AP80: 365108.48 | AQ80: 160162.45 | AR80: 20230124-095412_f2bda6db-5a5d-4682-88d0-f1fbc5f47696 | AT80: =(AP80-AQ80)/(365*24*2) -> 11.697833
A81: 16.29 | B81: 27.93 | C81: 5515.93 | D81: 7.59 | E81: [10.45, 33.04] | F81: [24.97, 1.92] | G81: [10.87, 10.87] | H81: [7.0, 6.55] | I81: 0 | J81: 436.9 | K81: =IF(E81=0,0, VALUE(MID(E81,2,FIND(",",E81)-2))+ VALUE(MID(F81,2,FIND(",",F81)-2))+ VALUE(MID(G81,2,FIND(",",G81)-2)) ) -> 46.29 | L81: =IF(E81=0,0, VALUE(MID(E81,FIND(",",E81)+1,FIND("]",E81)-FIND(",",E81)-1))+ VALUE(MID(F81,FIND(",",F81)+1,FIND("]",F81)-FIND(",",F81)-1))+ VALUE(MID(G81,FIND(",",G81)+1,FIND("]",G81)-FIND(",",G81)-1)) ) -> 45.83 | M81: =(K81-L81) -> 0.46 | N81: 7.04 | O81: 85.69 | P81: 86 | Q81: 12 | R81: 11.64 | S81: 10.47 | T81: 5.82 | U81: 12.63 | V81: 3530.2 | W81: 1077.31 | X81: 1536.78 | Y81: 823.38 | Z81: 7.07 | AA81: 1.6 | AB81: 4.39 | AC81: 66.67 | AD81: 490 | AE81: 4700 | AF81: 83.7 | AG81: 0.47 | AH81: 7.2 | AI81: 51.87 | AJ81: 60 | AK81: 9 | AL81: 9 | AM81: 0.44 | AN81: 294 | AO81: 297.93 | AP81: 396068.76 | AQ81: 128573.72 | AR81: 20230124-095412_85767bb6-6fbe-4a97-918c-61b0b7611781 | AT81: =(AP81-AQ81)/(365*24*2) -> 15.267982
A82: 17.31 | B82: 28.72 | C82: 5426.46 | D82: 7.57 | E82: [28.64, 62.75] | F82: [24.94, 1.27] | G82: [10.55, 10.55] | H82: [2.0, 12.43] | I82: 0 | J82: 750.7 | K82: =IF(E82=0,0, VALUE(MID(E82,2,FIND(",",E82)-2))+ VALUE(MID(F82,2,FIND(",",F82)-2))+ VALUE(MID(G82,2,FIND(",",G82)-2)) ) -> 64.13 | L82: =IF(E82=0,0, VALUE(MID(E82,FIND(",",E82)+1,FIND("]",E82)-FIND(",",E82)-1))+ VALUE(MID(F82,FIND(",",F82)+1,FIND("]",F82)-FIND(",",F82)-1))+ VALUE(MID(G82,FIND(",",G82)+1,FIND("]",G82)-FIND(",",G82)-1)) ) -> 74.57 | M82: =(K82-L82) -> -10.44 | N82: 7.25 | O82: 84.27 | P82: 61 | Q82: 17 | R82: 11.41 | S82: 12.43 | T82: 4.87 | U82: 7.23 | V82: 3472.93 | W82: 1035.15 | X82: 1247.35 | Y82: 743.37 | Z82: 5.16 | AA82: 1.49 | AB82: 4.59 | AC82: 70.06 | AD82: 490 | AE82: 4700 | AF82: 82.05 | AG82: 0.47 | AH82: 13.17 | AI82: 27.32 | AJ82: 60 | AK82: 9 | AL82: 9 | AM82: 0.83 | AN82: 294 | AO82: 301.46 | AP82: 360566.3 | AQ82: 206043.59 | AR82: 20230124-095935_7f52427f-d581-40f4-bd27-1df02358855d | AT82: =(AP82-AQ82)/(365*24*2) -> 8.8197894
... A85: 17.99 | B85: 29.6 | C85: 5385.11 | D85: 7.6 | E85: [15.55, 45.83] | F85: [25.0, 1.8] | G85: [11.39, 11.39] | H85: [2.0, 9.08] | I85: 0 | J85: 543.76 | K85: =IF(E85=0,0, VALUE(MID(E85,2,FIND(",",E85)-2))+ VALUE(MID(F85,2,FIND(",",F85)-2))+ VALUE(MID(G85,2,FIND(",",G85)-2)) ) -> 51.94 | L85: =IF(E85=0,0, VALUE(MID(E85,FIND(",",E85)+1,FIND("]",E85)-FIND(",",E85)-1))+ VALUE(MID(F85,FIND(",",F85)+1,FIND("]",F85)-FIND(",",F85)-1))+ VALUE(MID(G85,FIND(",",G85)+1,FIND("]",G85)-FIND(",",G85)-1)) ) -> 59.02 | M85: =(K85-L85) -> -7.08 | N85: 7.12 | O85: 84.7 | P85: 56 | Q85: 19.1 | R85: 11.61 | S85: 13.7 | T85: 4.29 | U85: 9.9 | V85: 3446.47 | W85: 1041.8 | X85: 1388.26 | Y85: 776.38 | Z85: 5.72 | AA85: 1.58 | AB85: 4.43 | AC85: 72.99 | AD85: 490 | AE85: 4700 | AF85: 83.46 | AG85: 0.47 | AH85: 9.37 | AI85: 37.4 | AJ85: 60 | AK85: 9 | AL85: 9 | AM85: 0.61 | AN85: 294 | AO85: 299.45 | AP85: 350532.87 | AQ85: 164462.9 | AR85: 20230124-095935_f85b8e87-0bbd-4f89-906b-06dceeef9f4a | AT85: =(AP85-AQ85)/(365*24*2) -> 10.620432
A86: 0 | B86: 0 | C86: 0 | D86: 0 | E86: 0 | F86: 0 | G86: 0 | H86: 0 | I86: 0 | J86: 0 | K86: =IF(E86=0,0, VALUE(MID(E86,2,FIND(",",E86)-2))+ VALUE(MID(F86,2,FIND(",",F86)-2))+ VALUE(MID(G86,2,FIND(",",G86)-2)) ) -> 0 | L86: =IF(E86=0,0, VALUE(MID(E86,FIND(",",E86)+1,FIND("]",E86)-FIND(",",E86)-1))+ VALUE(MID(F86,FIND(",",F86)+1,FIND("]",F86)-FIND(",",F86)-1))+ VALUE(MID(G86,FIND(",",G86)+1,FIND("]",G86)-FIND(",",G86)-1)) ) -> 0 | M86: =(K86-L86) -> 0 | N86: 0 | O86: 0 | P86: 0 | Q86: 0 | R86: 0 | S86: 0 | T86: 0 | U86: 0 | V86: 0 | W86: 0 | X86: 0 | Y86: 0 | Z86: 0 | AA86: 0 | AB86: 0 | AC86: 0 | AD86: 0 | AE86: 0 | AF86: 0 | AG86: 0 | AH86: 0 | AI86: 0 | AJ86: 0 | AK86: 0 | AL86: 0 | AM86: 0 | AN86: 0 | AO86: 0 | AP86: 0 | AQ86: 0 | AR86: 0 | AT86: =(AP86-AQ86)/(365*24*2) -> 0
A87: 18.32 | B87: 29.93 | C87: 5387.93 | D87: 7.61 | E87: [13.43, 43.47] | F87: [25.05, 1.62] | G87: [10.89, 10.89] | H87: [2.0, 8.61] | I87: 0 | J87: 502.8 | K87: =IF(E87=0,0, VALUE(MID(E87,2,FIND(",",E87)-2))+ VALUE(MID(F87,2,FIND(",",F87)-2))+ VALUE(MID(G87,2,FIND(",",G87)-2)) ) -> 49.37 | L87: =IF(E87=0,0, VALUE(MID(E87,FIND(",",E87)+1,FIND("]",E87)-FIND(",",E87)-1))+ VALUE(MID(F87,FIND(",",F87)+1,FIND("]",F87)-FIND(",",F87)-1))+ VALUE(MID(G87,FIND(",",G87)+1,FIND("]",G87)-FIND(",",G87)-1)) ) -> 55.98 | M87: =(K87-L87) -> -6.61 | N87: 7.08 | O87: 84.95 | P87: 56 | Q87: 19.5 | R87: 11.62 | S87: 14.05 | T87: 4.27 | U87: 10.72 | V87: 3448.28 | W87: 1044.73 | X87: 1419.55 | Y87: 783.77 | Z87: 5.73 | AA87: 1.61 | AB87: 4.39 | AC87: 73.15 | AD87: 490 | AE87: 4700 | AF87: 83.55 | AG87: 0.47 | AH87: 8.6 | AI87: 39.44 | AJ87: 60 | AK87: 9 | AL87: 9 | AM87: 0.57 | AN87: 294 | AO87: 299.17 | AP87: 348799.13 | AQ87: 154947.98 | AR87: 20230124-095935_72c5c4f1-aaf5-46a2-aa47-0ee64be5013b | AT87: =(AP87-AQ87)/(365*24*2) -> 11.064563
A88: 18.76 | B88: 30.06 | C88: 5417.08 | D88: 7.6 | E88: [19.77, 49.12] | F88: [24.99, 3.38] | G88: [10.78, 10.78] | H88: [2.0, 9.73] | I88: 0 | J88: 622.21 | K88: =IF(E88=0,0, VALUE(MID(E88,2,FIND(",",E88)-2))+ VALUE(MID(F88,2,FIND(",",F88)-2))+ VALUE(MID(G88,2,FIND(",",G88)-2)) ) -> 55.54 | L88: =IF(E88=0,0, VALUE(MID(E88,FIND(",",E88)+1,FIND("]",E88)-FIND(",",E88)-1))+ VALUE(MID(F88,FIND(",",F88)+1,FIND("]",F88)-FIND(",",F88)-1))+ VALUE(MID(G88,FIND(",",G88)+1,FIND("]",G88)-FIND(",",G88)-1)) ) -> 63.28 | M88: =(K88-L88) -> -7.74 | N88: 7.16 | O88: 84.73 | P88: 68 | Q88: 18.2 | R88: 11.29 | S88: 14.36 | T88: 4.4 | U88: 8.71 | V88: 3466.93 | W88: 1040.56 | X88: 1321.98 | Y88: 761.49 | Z88: 5.71 | AA88: 1.58 | AB88: 4.44 | AC88: 71.96 | AD88: 490 | AE88: 4700 | AF88: 81.22 | AG88: 0.47 | AH88: 10.54 | AI88: 34.88 | AJ88: 60 | AK88: 9 | AL88: 9 | AM88: 0.65 | AN88: 294 | AO88: 299.84 | AP88: 353595 | AQ88: 192871.25 | AR88: 20230124-095935_31629371-b0a8-456f-bdf3-60b2eb9ec76b | AT88: =(AP88-AQ88)/(365*24*2) -> 9.17373
A89: 18.18 | B89: 29.72 | C89: 5376.66 | D89: 7.6 | E89: [24.06, 58.48] | F89: [25.02, 0.18] | G89: [10.82, 10.82] | H89: [2.0, 11.58] | I89: 0 | J89: 687.4 | K89: =IF(E89=0,0, VALUE(MID(E89,2,FIND(",",E89)-2))+ VALUE(MID(F89,2,FIND(",",F89)-2))+ VALUE(MID(G89,2,FIND(",",G89)-2)) ) -> 59.9 | L89: =IF(E89=0,0, VALUE(MID(E89,FIND(",",E89)+1,FIND("]",E89)-FIND(",",E89)-1))+ VALUE(MID(F89,FIND(",",F89)+1,FIND("]",F89)-FIND(",",F89)-1))+ VALUE(MID(G89,FIND(",",G89)+1,FIND("]",G89)-FIND(",",G89)-1)) ) -> 69.48 | M89: =(K89-L89) -> -9.58 | N89: 7.21 | O89: 85.21 | P89: 56 | Q89: 19.5 | R89: 11.54 | S89: 14.05 | T89: 4.13 | U89: 7.82 | V89: 3441.06 | W89: 1029.07 | X89: 1271.58 | Y89: 745.67 | Z89: 5.17 | AA89: 1.54 | AB89: 4.51 | AC89: 73.64 | AD89: 490 | AE89: 4700 | AF89: 83.01 | AG89: 0.47 | AH89: 12.17 | AI89: 29.33 | AJ89: 60 | AK89: 9 | AL89: 9 | AM89: 0.77 | AN89: 294 | AO89: 300.95 | AP89: 357724.17 | AQ89: 180548.98 | AR89: 20230124-095935_9cf267c2-8d51-4c90-90b7-ab3040a8b89f | AT89: =(AP89-AQ89)/(365*24*2) -> 10.112739
A90: 18.67 | B90: 30.22 | C90: 5380.73 | D90: 7.59 | E90: [24.56, 58.55] | F90: [24.97, 0.57] | G90: [10.44, 10.44] | H90: [2.0, 11.59] | I90: 0 | J90: 697.41 | K90: =IF(E90=0,0, VALUE(MID(E90,2,FIND(",",E90)-2))+ VALUE(MID(F90,2,FIND(",",F90)-2))+ VALUE(MID(G90,2,FIND(",",G90)-2)) ) -> 59.97 | L90: =IF(E90=0,0, VALUE(MID(E90,FIND(",",E90)+1,FIND("]",E90)-FIND(",",E90)-1))+ VALUE(MID(F90,FIND(",",F90)+1,FIND("]",F90)-FIND(",",F90)-1))+ VALUE(MID(G90,FIND(",",G90)+1,FIND("]",G90)-FIND(",",G90)-1)) ) -> 69.56 | M90: =(K90-L90) -> -9.59 | N90: 7.21 | O90: 84.85 | P90: 57 | Q90: 19.8 | R90: 11.55 | S90: 14.44 | T90: 4.22 | U90: 7.72 | V90: 3443.67 | W90: 1028.69 | X90: 1262.3 | Y90: 743.35 | Z90: 5.17 | AA90: 1.54 | AB90: 4.51 | AC90: 73.24 | AD90: 490 | AE90: 4700 | AF90: 83.08 | AG90: 0.47 | AH90: 12.37 | AI90: 29.29 | AJ90: 60 | AK90: 9 | AL90: 9 | AM90: 0.77 | AN90: 294 | AO90: 300.96 | AP90: 357228.02 | AQ90: 185289.66 | AR90: 20230124-095935_2fc457b5-2525-4207-8b72-3b7c527172fa | AT90: =(AP90-AQ90)/(365*24*2) -> 9.8138333
A91: 18.51 | B91: 30.08 | C91: 5339.62 | D91: 7.59 | E91: [25.2, 59.68] | F91: [25.05, 0.39] | G91: [10.83, 10.83] | H91: [2.0, 11.82] | I91: 0 | J91: 702.96 | K91: =IF(E91=0,0, VALUE(MID(E91,2,FIND(",",E91)-2))+ VALUE(MID(F91,2,FIND(",",F91)-2))+ VALUE(MID(G91,2,FIND(",",G91)-2)) ) -> 61.08 | L91: =IF(E91=0,0, VALUE(MID(E91,FIND(",",E91)+1,FIND("]",E91)-FIND(",",E91)-1))+ VALUE(MID(F91,FIND(",",F91)+1,FIND("]",F91)-FIND(",",F91)-1))+ VALUE(MID(G91,FIND(",",G91)+1,FIND("]",G91)-FIND(",",G91)-1)) ) -> 70.9 | M91: =(K91-L91) -> -9.82 | N91: 7.22 | O91: 85.18 | P91: 55 | Q91: 20.1 | R91: 11.57 | S91: 14.45 | T91: 4.06 | U91: 7.6 | V91: 3417.36 | W91: 1021.18 | X91: 1254.22 | Y91: 738.38 | Z91: 5.17 | AA91: 1.53 | AB91: 4.53 | AC91: 74 | AD91: 490 | AE91: 4700 | AF91: 83.19 | AG91: 0.47 | AH91: 12.61 | AI91: 28.73 | AJ91: 60 | AK91: 9 | AL91: 9 | AM91: 0.79 | AN91: 294 | AO91: 301.09 | AP91: 359063.86 | AQ91: 186672.14 | AR91: 20230124-095935_2527abfa-c0c9-4b2c-b9ef-12ea68e712f1 | AT91: =(AP91-AQ91)/(365*24*2) -> 9.83971
A92: 17.8 | B92: 29.44 | C92: 5371.53 | D92: 7.6 | E92: [9.2, 39.37] | F92: [24.96, 0.59] | G92: [10.72, 10.72] | H92: [2.0, 7.8] | I92: 0 | J92: 406.93 | K92: =IF(E92=0,0, VALUE(MID(E92,2,FIND(",",E92)-2))+ VALUE(MID(F92,2,FIND(",",F92)-2))+ VALUE(MID(G92,2,FIND(",",G92)-2)) ) -> 44.88 | L92: =IF(E92=0,0, VALUE(MID(E92,FIND(",",E92)+1,FIND("]",E92)-FIND(",",E92)-1))+ VALUE(MID(F92,FIND(",",F92)+1,FIND("]",F92)-FIND(",",F92)-1))+ VALUE(MID(G92,FIND(",",G92)+1,FIND("]",G92)-FIND(",",G92)-1)) ) -> 50.68 | M92: =(K92-L92) -> -5.8 | N92: 7.01 | O92: 85.13 | P92: 57 | Q92: 18.6 | R92: 11.65 | S92: 13.38 | T92: 4.42 | U92: 13.2 | V92: 3437.78 | W92: 1052.77 | X92: 1538.02 | Y92: 811.95 | Z92: 5.76 | AA92: 1.63 | AB92: 4.34 | AC92: 72.49 | AD92: 490 | AE92: 4700 | AF92: 83.74 | AG92: 0.47 | AH92: 6.86 | AI92: 43.55 | AJ92: 60 | AK92: 9 | AL92: 9 | AM92: 0.52 | AN92: 294 | AO92: 298.68 | AP92: 343836.89 | AQ92: 130312.69 | AR92: 20230124-095935_50f08e86-7908-4c63-87e5-91d39e18e12e | AT92: =(AP92-AQ92)/(365*24*2) -> 12.187454
A93: 18.71 | B93: 30.3 | C93: 5389.47 | D93: 7.6 | E93: [23.92, 58.22] | F93: [25.03, 0.26] | G93: [10.69, 10.69] | H93: [2.0, 11.53] | I93: 0 | J93: 686.06 | K93: =IF(E93=0,0, VALUE(MID(E93,2,FIND(",",E93)-2))+ VALUE(MID(F93,2,FIND(",",F93)-2))+ VALUE(MID(G93,2,FIND(",",G93)-2)) ) -> 59.64 | L93: =IF(E93=0,0, VALUE(MID(E93,FIND(",",E93)+1,FIND("]",E93)-FIND(",",E93)-1))+ VALUE(MID(F93,FIND(",",F93)+1,FIND("]",F93)-FIND(",",F93)-1))+ VALUE(MID(G93,FIND(",",G93)+1,FIND("]",G93)-FIND(",",G93)-1)) ) -> 69.17 | M93: =(K93-L93) -> -9.53 | N93: 7.21 | O93: 85.27 | P93: 56 | Q93: 20.2 | R93: 11.58 | S93: 14.67 | T93: 4.04 | U93: 7.86 | V93: 3449.26 | W93: 1031.35 | X93: 1273.63 | Y93: 747.09 | Z93: 5.17 | AA93: 1.56 | AB93: 4.49 | AC93: 74.12 | AD93: 490 | AE93: 4700 | AF93: 83.3 | AG93: 0.47 | AH93: 12.15 | AI93: 29.46 | AJ93: 60 | AK93: 9 | AL93: 9 | AM93: 0.77 | AN93: 294 | AO93: 300.92 | AP93: 357618.28 | AQ93: 180652.63 | AR93: 20230124-095935_c6fa23cf-7316-4cec-9f77-6730ee0c7e55 | AT93: =(AP93-AQ93)/(365*24*2) -> 10.100779
A94: 16.97 | B94: 28.47 | C94: 5448.08 | D94: 7.59 | E94: [5.27, 32.85] | F94: [25.12, 2.05] | G94: [10.67, 10.67] | H94: [2.0, 6.51] | I94: 0 | J94: 297.01 | K94: =IF(E94=0,0, VALUE(MID(E94,2,FIND(",",E94)-2))+ VALUE(MID(F94,2,FIND(",",F94)-2))+ VALUE(MID(G94,2,FIND(",",G94)-2)) ) -> 41.06 | L94: =IF(E94=0,0, VALUE(MID(E94,FIND(",",E94)+1,FIND("]",E94)-FIND(",",E94)-1))+ VALUE(MID(F94,FIND(",",F94)+1,FIND("]",F94)-FIND(",",F94)-1))+ VALUE(MID(G94,FIND(",",G94)+1,FIND("]",G94)-FIND(",",G94)-1)) ) -> 45.57 | M94: =(K94-L94) -> -4.51 | N94: 6.93 | O94: 84.44 | P94: 65 | Q94: 15.9 | R94: 11.5 | S94: 11.89 | T94: 5.08 | U94: 18.34 | V94: 3486.77 | W94: 1089.83 | X94: 1801.48 | Y94: 883.65 | Z94: 6.31 | AA94: 1.69 | AB94: 4.22 | AC94: 69.37 | AD94: 490 | AE94: 4700 | AF94: 82.69 | AG94: 0.47 | AH94: 4.77 | AI94: 52.16 | AJ94: 60 | AK94: 9 | AL94: 9 | AM94: 0.43 | AN94: 294 | AO94: 297.91 | AP94: 342329.63 | AQ94: 129405.91 | AR94: 20230124-095935_9d952115-40c3-461d-a9c6-8ba6f027add8 | AT94: =(AP94-AQ94)/(365*24*2) -> 12.15318
A95: 18.4 | B95: 29.64 | C95: 5438.44 | D95: 7.62 | E95: [11.29, 41.33] | F95: [24.97, 1.12] | G95: [10.76, 10.76] | H95: [2.0, 8.19] | I95: 0 | J95: 456.99 | K95: =IF(E95=0,0, VALUE(MID(E95,2,FIND(",",E95)-2))+ VALUE(MID(F95,2,FIND(",",F95)-2))+ VALUE(MID(G95,2,FIND(",",G95)-2)) ) -> 47.02 | L95: =IF(E95=0,0, VALUE(MID(E95,FIND(",",E95)+1,FIND("]",E95)-FIND(",",E95)-1))+ VALUE(MID(F95,FIND(",",F95)+1,FIND("]",F95)-FIND(",",F95)-1))+ VALUE(MID(G95,FIND(",",G95)+1,FIND("]",G95)-FIND(",",G95)-1)) ) -> 53.21 | M95: =(K95-L95) -> -6.19 | N95: 7.05 | O95: 84.94 | P95: 73 | Q95: 16.7 | R95: 11.23 | S95: 13.55 | T95: 4.85 | U95: 11.9 | V95: 3480.6 | W95: 1059.24 | X95: 1484.88 | Y95: 804.01 | Z95: 5.74 | AA95: 1.65 | AB95: 4.33 | AC95: 69.84 | AD95: 490 | AE95: 4700 | AF95: 80.78 | AG95: 0.47 | AH95: 7.41 | AI95: 41.48 | AJ95: 60 | AK95: 9 | AL95: 9 | AM95: 0.55 | AN95: 294 | AO95: 298.91 | AP95: 345905.34 | AQ95: 142599.6 | AR95: 20230124-095935_3c92dbac-79df-4625-9a92-edad34775c9c | AT95: =(AP95-AQ95)/(365*24*2) -> 11.604209
A96: 18.78 | B96: 30.01 | C96: 5410.71 | D96: 7.58 | E96: [28.41, 62.56] | F96: [25.09, 1.33] | G96: [10.45, 10.45] | H96: [2.0, 12.39] | I96: 0 | J96: 746.95 | K96: =IF(E96=0,0, VALUE(MID(E96,2,FIND(",",E96)-2))+ VALUE(MID(F96,2,FIND(",",F96)-2))+ VALUE(MID(G96,2,FIND(",",G96)-2)) ) -> 63.95 | L96: =IF(E96=0,0, VALUE(MID(E96,FIND(",",E96)+1,FIND("]",E96)-FIND(",",E96)-1))+ VALUE(MID(F96,FIND(",",F96)+1,FIND("]",F96)-FIND(",",F96)-1))+ VALUE(MID(G96,FIND(",",G96)+1,FIND("]",G96)-FIND(",",G96)-1)) ) -> 74.34 | M96: =(K96-L96) -> -10.39 | N96: 7.24 | O96: 85.13 | P96: 72 | Q96: 17.4 | R96: 11.23 | S96: 14.09 | T96: 4.68 | U96: 7.24 | V96: 3462.85 | W96: 1032.05 | X96: 1243.66 | Y96: 741.06 | Z96: 5.16 | AA96: 1.53 | AB96: 4.53 | AC96: 70.57 | AD96: 490 | AE96: 4700 | AF96: 80.76 | AG96: 0.47 | AH96: 12.93 | AI96: 27.41 | AJ96: 60 | AK96: 9 | AL96: 9 | AM96: 0.83 | AN96: 294 | AO96: 301.43 | AP96: 362056.53 | AQ96: 206209.5 | AR96: 20230124-095935_4abc60a9-a8b6-4fce-8ea8-86513755599d | AT96: =(AP96-AQ96)/(365*24*2) -> 8.8953784
...

Sheet N2
A1: supply_temp | B1: return_temp | C1: ct_conductivity | D1: ct_ph | E1: Bore | F1: CWRO | G1: BoilerBD | H1: BD | I1: scheme | J1: mu_conductivity | K1: mu_flow(PV) | L1: mu-flow(OV) | M1: m-saving(PV-OV) | N1: mu_ph | O1: cooling_tower_level | P1: relative_humidity | Q1: ambient_temp | R1: delta_temp | S1: wetBulb_temp | T1: approach_temp | U1: cond_coc | V1: ct_tds | W1: ct_ca | X1: ct_alk | Y1: ct_chloride | Z1: flow_cycle | AA1: sat_index | AB1: sta_index | AC1: perf_index | AD1: system_vol | AE1: rec_rate | AF1: evap_loss | AG1: drift_loss | AH1: blowdown_coc | AI1: hold_time_index | AJ1: dosing_residual | AK1: dosing_contact_time | AL1: dosing_density | AM1: dosing_continuous | AN1: dosing_initial | AO1: dosing_slug | AP1: currentOperatingCost | AQ1: newOperatingCost | AR1: updatedDateTime | AS1: Date and Time | AT1: =SUM(AT2:AT251) -> 2113.5062 | AU1: Total Savings
A2: 20.45 | B2: 28.93 | C2: 5512.81 | D2: 7.6 | E2: [37.04, 58.45] | F2: [19.97, 3.97] | G2: [7.08, 7.08] | H2: [6.18, 11.58] | I2: 0 | J2: 934.11 | K2: =IF(E2=0,0, VALUE(MID(E2,2,FIND(",",E2)-2))+ VALUE(MID(F2,2,FIND(",",F2)-2))+ VALUE(MID(G2,2,FIND(",",G2)-2)) ) -> 64.09 | L2: =IF(E2=0,0, VALUE(MID(E2,FIND(",",E2)+1,FIND("]",E2)-FIND(",",E2)-1))+ VALUE(MID(F2,FIND(",",F2)+1,FIND("]",F2)-FIND(",",F2)-1))+ VALUE(MID(G2,FIND(",",G2)+1,FIND("]",G2)-FIND(",",G2)-1)) ) -> 69.5 | M2: =(K2-L2) -> -5.41 | N2: 7.35 | O2: 89.04 | P2: 59 | Q2: 21.1 | R2: 8.49 | S2: 15.87 | T2: 4.58 | U2: 5.9 | V2: 3528.2 | W2: 1043.33 | X2: 1183.31 | Y2: 733.34 | Z2: 5.53 | AA2: 1.56 | AB2: 4.48 | AC2: 64.94 | AD2: 680 | AE2: 5900 | AF2: 76.61 | AG2: 0.59 | AH2: 15.63 | AI2: 40.68 | AJ2: 60 | AK2: 9 | AL2: 9 | AM2: 0.77 | AN2: 408 | AO2: 414.95 | AP2: 346286.15 | AQ2: 223820.61 | AR2: 20230124-093759_8f3cf142-09ac-4146-806e-26f92db6205a | AT2: =(AP2-AQ2)/(365*24*2) -> 6.9900422 | AU2: =SUM(AT2:AT251) -> 2113.5062
A3: 19.8 | B3: 28.36 | C3: 5481.54 | D3: 7.6 | E3: [39.92, 41.08] | F3: [19.98, 17.67] | G3: [6.72, 6.72] | H3: [9.34, 8.18] | I3: 0 | J3: 963.61 | K3: =IF(E3=0,0, VALUE(MID(E3,2,FIND(",",E3)-2))+ VALUE(MID(F3,2,FIND(",",F3)-2))+ VALUE(MID(G3,2,FIND(",",G3)-2)) ) -> 66.62 | L3: =IF(E3=0,0, VALUE(MID(E3,FIND(",",E3)+1,FIND("]",E3)-FIND(",",E3)-1))+ VALUE(MID(F3,FIND(",",F3)+1,FIND("]",F3)-FIND(",",F3)-1))+ VALUE(MID(G3,FIND(",",G3)+1,FIND("]",G3)-FIND(",",G3)-1)) ) -> 65.47 | M3: =(K3-L3) -> 1.15 | N3: 7.37 | O3: 88.97 | P3: 67 | Q3: 18.3 | R3: 8.56 | S3: 14.33 | T3: 5.46 | U3: 5.69 | V3: 3508.19 | W3: 1036.27 | X3: 1165.35 | Y3: 726.2 | Z3: 8.14 | AA3: 1.54 | AB3: 4.52 | AC3: 61.06 | AD3: 680 | AE3: 5900 | AF3: 77.3 | AG3: 0.59 | AH3: 16.49 | AI3: 57.59 | AJ3: 60 | AK3: 9 | AL3: 9 | AM3: 0.55 | AN3: 408 | AO3: 412.91 | AP3: 380823.23 | AQ3: 341717.71 | AR3: 20230124-093759_a884498a-9014-4d7b-93b0-1726eebac697 | AT3: =(AP3-AQ3)/(365*24*2) -> 2.2320502
A4: 21.07 | B4: 29.56 | C4: 5502.85 | D4: 7.6 | E4: [35.17, 57.06] | F4: [20.0, 3.77] | G4: [7.02, 7.02] | H4: [5.64, 11.31] | I4: 0 | J4: 916.17 | K4: =IF(E4=0,0, VALUE(MID(E4,2,FIND(",",E4)-2))+ VALUE(MID(F4,2,FIND(",",F4)-2))+ VALUE(MID(G4,2,FIND(",",G4)-2)) ) -> 62.19 | L4: =IF(E4=0,0, VALUE(MID(E4,FIND(",",E4)+1,FIND("]",E4)-FIND(",",E4)-1))+ VALUE(MID(F4,FIND(",",F4)+1,FIND("]",F4)-FIND(",",F4)-1))+ VALUE(MID(G4,FIND(",",G4)+1,FIND("]",G4)-FIND(",",G4)-1)) ) -> 67.85 | M4: =(K4-L4) -> -5.66 | N4: 7.34 | O4: 89.03 | P4: 63 | Q4: 21.3 | R4: 8.49 | S4: 16.58 | T4: 4.49 | U4: 6.01 | V4: 3521.82 | W4: 1041.77 | X4: 1185.44 | Y4: 732.98 | Z4: 5.5 | AA4: 1.58 | AB4: 4.45 | AC4: 65.41 | AD4: 680 | AE4: 5900 | AF4: 76.65 | AG4: 0.59 | AH4: 15.31 | AI4: 41.67 | AJ4: 60 | AK4: 9 | AL4: 9 | AM4: 0.75 | AN4: 408 | AO4: 414.79 | AP4: 339527.78 | AQ4: 217337.16 | AR4: 20230124-093759_cffc3147-744b-4994-ace0-e0882e8a1dd7 | AT4: =(AP4-AQ4)/(365*24*2) -> 6.9743505
A5: 20.53 | B5: 29.16 | C5: 5547.23 | D5: 7.61 | E5: [34.35, 34.61] | F5: [19.98, 16.99] | G5: [7.05, 7.05] | H5: [9.63, 6.9] | I5: 0 | J5: 907.68 | K5: =IF(E5=0,0, VALUE(MID(E5,2,FIND(",",E5)-2))+ VALUE(MID(F5,2,FIND(",",F5)-2))+ VALUE(MID(G5,2,FIND(",",G5)-2)) ) -> 61.38 | L5: =IF(E5=0,0, VALUE(MID(E5,FIND(",",E5)+1,FIND("]",E5)-FIND(",",E5)-1))+ VALUE(MID(F5,FIND(",",F5)+1,FIND("]",F5)-FIND(",",F5)-1))+ VALUE(MID(G5,FIND(",",G5)+1,FIND("]",G5)-FIND(",",G5)-1)) ) -> 58.65 | M5: =(K5-L5) -> 2.73 | N5: 7.33 | O5: 89.09 | P5: 59 | Q5: 20 | R5: 8.63 | S5: 14.88 | T5: 5.65 | U5: 6.11 | V5: 3550.23 | W5: 1050.45 | X5: 1197.93 | Y5: 739.63 | Z5: 8.9 | AA5: 1.58 | AB5: 4.45 | AC5: 60.44 | AD5: 680 | AE5: 5900 | AF5: 77.91 | AG5: 0.59 | AH5: 15.24 | AI5: 68.29 | AJ5: 60 | AK5: 9 | AL5: 9 | AM5: 0.46 | AN5: 408 | AO5: 412.14 | AP5: 379117.53 | AQ5: 314998.12 | AR5: 20230124-093759_9f0a1368-5ec7-48f3-a1f7-b03589439cab | AT5: =(AP5-AQ5)/(365*24*2) -> 3.6597837
A6: 20.88 | B6: 29.38 | C6: 5575.31 | D6: 7.59 | E6: [39.89, 45.02] | F6: [20.02, 15.12] | G6: [7.03, 7.03] | H6: [8.72, 8.96] | I6: 0 | J6: 959.65 | K6: =IF(E6=0,0, VALUE(MID(E6,2,FIND(",",E6)-2))+ VALUE(MID(F6,2,FIND(",",F6)-2))+ VALUE(MID(G6,2,FIND(",",G6)-2)) ) -> 66.94 | L6: =IF(E6=0,0, VALUE(MID(E6,FIND(",",E6)+1,FIND("]",E6)-FIND(",",E6)-1))+ VALUE(MID(F6,FIND(",",F6)+1,FIND("]",F6)-FIND(",",F6)-1))+ VALUE(MID(G6,FIND(",",G6)+1,FIND("]",G6)-FIND(",",G6)-1)) ) -> 67.17 | M6: =(K6-L6) -> -0.23 | N6: 7.37 | O6: 88.78 | P6: 85 | Q6: 18.9 | R6: 8.51 | S6: 17.08 | T6: 3.8 | U6: 5.81 | V6: 3568.2 | W6: 1054.47 | X6: 1189.13 | Y6: 739.77 | Z6: 7.47 | AA6: 1.57 | AB6: 4.46 | AC6: 69.13 | AD6: 680 | AE6: 5900 | AF6: 76.78 | AG6: 0.59 | AH6: 15.96 | AI6: 52.62 | AJ6: 60 | AK6: 9 | AL6: 9 | AM6: 0.6 | AN6: 408 | AO6: 413.37 | AP6: 375224.71 | AQ6: 322015.99 | AR6: 20230124-093759_e697bf3c-588b-4d89-9b61-67d892014333 | AT6: =(AP6-AQ6)/(365*24*2) -> 3.0370274
A7: 20.17 | B7: 28.68 | C7: 5527.33 | D7: 7.6 | E7: [44.59, 44.59] | F7: [20.0, 20.0] | G7: [7.04, 7.04] | H7: [10.0, 10.0] | I7: 0 | J7: 998.03 | K7: =IF(E7=0,0, VALUE(MID(E7,2,FIND(",",E7)-2))+ VALUE(MID(F7,2,FIND(",",F7)-2))+ VALUE(MID(G7,2,FIND(",",G7)-2)) ) -> 71.63 | L7: =IF(E7=0,0, VALUE(MID(E7,FIND(",",E7)+1,FIND("]",E7)-FIND(",",E7)-1))+ VALUE(MID(F7,FIND(",",F7)+1,FIND("]",F7)-FIND(",",F7)-1))+ VALUE(MID(G7,FIND(",",G7)+1,FIND("]",G7)-FIND(",",G7)-1)) ) -> 71.63 | M7: =(K7-L7) -> 0 | N7: 7.4 | O7: 88.97 | P7: 64 | Q7: 19.7 | R7: 8.51 | S7: 15.25 | T7: 4.92 | U7: 5.54 | V7: 3537.49 | W7: 1044.58 | X7: 1169.32 | Y7: 731.11 | Z7: 7.16 | AA7: 1.55 | AB7: 4.5 | AC7: 63.36 | AD7: 680 | AE7: 5900 | AF7: 76.85 | AG7: 0.59 | AH7: 16.93 | AI7: 47.12 | AJ7: 60 | AK7: 9 | AL7: 9 | AM7: 0.67 | AN7: 408 | AO7: 414 | AP7: 392065.22 | AQ7: 392065.22 | AR7: 20230124-093759_5bf3c0ad-e364-4209-aee7-a3fb00439d48 | AT7: =(AP7-AQ7)/(365*24*2) -> 0
A8: 19.5 | B8: 28.08 | C8: 5464.1 | D8: 7.6 | E8: [37.45, 46.7] | F8: [20.02, 11.58] | G8: [6.67, 6.67] | H8: [8.47, 9.28] | I8: 0 | J8: 941.24 | K8: =IF(E8=0,0, VALUE(MID(E8,2,FIND(",",E8)-2))+ VALUE(MID(F8,2,FIND(",",F8)-2))+ VALUE(MID(G8,2,FIND(",",G8)-2)) ) -> 64.14 | L8: =IF(E8=0,0, VALUE(MID(E8,FIND(",",E8)+1,FIND("]",E8)-FIND(",",E8)-1))+ VALUE(MID(F8,FIND(",",F8)+1,FIND("]",F8)-FIND(",",F8)-1))+ VALUE(MID(G8,FIND(",",G8)+1,FIND("]",G8)-FIND(",",G8)-1)) ) -> 64.95 | M8: =(K8-L8) -> -0.81 | N8: 7.35 | O8: 88.97 | P8: 66 | Q8: 18.2 | R8: 8.58 | S8: 14.12 | T8: 5.38 | U8: 5.81 | V8: 3497.03 | W8: 1033.38 | X8: 1166.81 | Y8: 725.07 | Z8: 6.91 | AA8: 1.53 | AB8: 4.54 | AC8: 61.45 | AD8: 680 | AE8: 5900 | AF8: 77.46 | AG8: 0.59 | AH8: 16.12 | AI8: 50.78 | AJ8: 60 | AK8: 9 | AL8: 9 | AM8: 0.62 | AN8: 408 | AO8: 413.57 | AP8: 370313.06 | AQ8: 283052.14 | AR8: 20230124-093759_f9e7fcbc-77c4-4dc7-8ef4-49ac28693c79 | AT8: =(AP8-AQ8)/(365*24*2) -> 4.9806461
A9: 20.44 | B9: 28.98 | C9: 5512.02 | D9: 7.6 | E9: [37.53, 36.6] | F9: [20.23, 18.46] | G9: [6.97, 6.97] | H9: [10.0, 7.3] | I9: 0 | J9: 936.05 | K9: =IF(E9=0,0, VALUE(MID(E9,2,FIND(",",E9)-2))+ VALUE(MID(F9,2,FIND(",",F9)-2))+ VALUE(MID(G9,2,FIND(",",G9)-2)) ) -> 64.73 | L9: =IF(E9=0,0, VALUE(MID(E9,FIND(",",E9)+1,FIND("]",E9)-FIND(",",E9)-1))+ VALUE(MID(F9,FIND(",",F9)+1,FIND("]",F9)-FIND(",",F9)-1))+ VALUE(MID(G9,FIND(",",G9)+1,FIND("]",G9)-FIND(",",G9)-1)) ) -> 62.03 | M9: =(K9-L9) -> 2.7 | N9: 7.35 | O9: 88.92 | P9: 73 | Q9: 18.4 | R9: 8.54 | S9: 15.15 | T9: 5.28 | U9: 5.89 | V9: 3527.69 | W9: 1042.86 | X9: 1180.61 | Y9: 732.46 | Z9: 8.87 | AA9: 1.56 | AB9: 4.49 | AC9: 61.79 | AD9: 680 | AE9: 5900 | AF9: 77.13 | AG9: 0.59 | AH9: 15.78 | AI9: 64.57 | AJ9: 60 | AK9: 9 | AL9: 9 | AM9: 0.49 | AN9: 408 | AO9: 412.38 | AP9: 388777.16 | AQ9: 338776.81 | AR9: 20230124-093759_73ba74f0-c493-4a9d-a540-f7430c20f7bd | AT9: =(AP9-AQ9)/(365*24*2) -> 2.8539013
A10: 20.6 | B10: 29.12 | C10: 5515.97 | D10: 7.6 | E10: [35.19, 56.71] | F10: [19.99, 3.77] | G10: [6.95, 6.95] | H10: [5.93, 11.24] | I10: 0 | J10: 917 | K10: =IF(E10=0,0, VALUE(MID(E10,2,FIND(",",E10)-2))+ VALUE(MID(F10,2,FIND(",",F10)-2))+ VALUE(MID(G10,2,FIND(",",G10)-2)) ) -> 62.13 | L10: =IF(E10=0,0, VALUE(MID(E10,FIND(",",E10)+1,FIND("]",E10)-FIND(",",E10)-1))+ VALUE(MID(F10,FIND(",",F10)+1,FIND("]",F10)-FIND(",",F10)-1))+ VALUE(MID(G10,FIND(",",G10)+1,FIND("]",G10)-FIND(",",G10)-1)) ) -> 67.43 | M10: =(K10-L10) -> -5.3 | N10: 7.34 | O10: 88.92 | P10: 58 | Q10: 21 | R10: 8.52 | S10: 15.64 | T10: 4.96 | U10: 6.02 | V10: 3530.22 | W10: 1044.14 | X10: 1187.37 | Y10: 734.46 | Z10: 5.53 | AA10: 1.57 | AB10: 4.47 | AC10: 63.23 | AD10: 680 | AE10: 5900 | AF10: 76.94 | AG10: 0.59 | AH10: 15.34 | AI10: 41.93 | AJ10: 60 | AK10: 9 | AL10: 9 | AM10: 0.75 | AN10: 408 | AO10: 414.74 | AP10: 342397.17 | AQ10: 216253.17 | AR10: 20230124-093759_a87f9bba-c063-48b0-9805-748c97392c9e | AT10: =(AP10-AQ10)/(365*24*2) -> 7.2
A11: 19.94 | B11: 28.56 | C11: 5481.47 | D11: 7.6 | E11: [37.75, 55.52] | F11: [20.05, 3.65] | G11: [6.85, 6.85] | H11: [9.63, 11.0] | I11: 0 | J11: 941.83 | K11: =IF(E11=0,0, VALUE(MID(E11,2,FIND(",",E11)-2))+ VALUE(MID(F11,2,FIND(",",F11)-2))+ VALUE(MID(G11,2,FIND(",",G11)-2)) ) -> 64.65 | L11: =IF(E11=0,0, VALUE(MID(E11,FIND(",",E11)+1,FIND("]",E11)-FIND(",",E11)-1))+ VALUE(MID(F11,FIND(",",F11)+1,FIND("]",F11)-FIND(",",F11)-1))+ VALUE(MID(G11,FIND(",",G11)+1,FIND("]",G11)-FIND(",",G11)-1)) ) -> 66.02 | M11: =(K11-L11) -> -1.37 | N11: 7.36 | O11: 89.01 | P11: 72 | Q11: 18.2 | R11: 8.62 | S11: 14.84 | T11: 5.09 | U11: 5.82 | V11: 3508.14 | W11: 1036.87 | X11: 1171.95 | Y11: 727.85 | Z11: 5.88 | AA11: 1.54 | AB11: 4.51 | AC11: 62.87 | AD11: 680 | AE11: 5900 | AF11: 77.85 | AG11: 0.59 | AH11: 16.15 | AI11: 42.83 | AJ11: 60 | AK11: 9 | AL11: 9 | AM11: 0.73 | AN11: 408 | AO11: 414.6 | AP11: 382833.87 | AQ11: 211213.76 | AR11: 20230124-093759_27d58fd8-c9d7-41fe-ae29-27a121326add | AT11: =(AP11-AQ11)/(365*24*2) -> 9.7956684
A12: 20.22 | B12: 28.76 | C12: 5518.87 | D12: 7.6 | E12: [31.83, 37.66] | F12: [20.04, 15.33] | G12: [7.01, 7.01] | H12: [6.38, 7.5] | I12: 0 | J12: 880.22 | K12: =IF(E12=0,0, VALUE(MID(E12,2,FIND(",",E12)-2))+ VALUE(MID(F12,2,FIND(",",F12)-2))+ VALUE(MID(G12,2,FIND(",",G12)-2)) ) -> 58.88 | L12: =IF(E12=0,0, VALUE(MID(E12,FIND(",",E12)+1,FIND("]",E12)-FIND(",",E12)-1))+ VALUE(MID(F12,FIND(",",F12)+1,FIND("]",F12)-FIND(",",F12)-1))+ VALUE(MID(G12,FIND(",",G12)+1,FIND("]",G12)-FIND(",",G12)-1)) ) -> 60 | M12: =(K12-L12) -> -1.12 | N12: 7.31 | O12: 89.06 | P12: 59 | Q12: 21.2 | R12: 8.54 | S12: 15.95 | T12: 4.26 | U12: 6.27 | V12: 3532.08 | W12: 1045.69 | X12: 1199.35 | Y12: 737.61 | Z12: 7.85 | AA12: 1.56 | AB12: 4.47 | AC12: 66.72 | AD12: 680 | AE12: 5900 | AF12: 77.13 | AG12: 0.59 | AH12: 14.64 | AI12: 62.83 | AJ12: 60 | AK12: 9 | AL12: 9 | AM12: 0.5 | AN12: 408 | AO12: 412.5 | AP12: 344562.17 | AQ12: 303349.62 | AR12: 20230124-093759_bf97e8b9-d8f1-4edf-bea6-381a9adeadb3 | AT12: =(AP12-AQ12)/(365*24*2) -> 2.3523145
A13: 20.62 | B13: 29.11 | C13: 5508.85 | D13: 7.6 | E13: [33.78, 55.88] | F13: [20.17, 3.4] | G13: [7.16, 7.16] | H13: [5.74, 11.07] | I13: 0 | J13: 898.01 | K13: =IF(E13=0,0, VALUE(MID(E13,2,FIND(",",E13)-2))+ VALUE(MID(F13,2,FIND(",",F13)-2))+ VALUE(MID(G13,2,FIND(",",G13)-2)) ) -> 61.11 | L13: =IF(E13=0,0, VALUE(MID(E13,FIND(",",E13)+1,FIND("]",E13)-FIND(",",E13)-1))+ VALUE(MID(F13,FIND(",",F13)+1,FIND("]",F13)-FIND(",",F13)-1))+ VALUE(MID(G13,FIND(",",G13)+1,FIND("]",G13)-FIND(",",G13)-1)) ) -> 66.44 | M13: =(K13-L13) -> -5.33 | N13: 7.33 | O13: 89.08 | P13: 62 | Q13: 21.1 | R13: 8.49 | S13: 16.26 | T13: 4.36 | U13: 6.13 | V13: 3525.66 | W13: 1043.48 | X13: 1192.92 | Y13: 735.34 | Z13: 5.52 | AA13: 1.57 | AB13: 4.47 | AC13: 66.07 | AD13: 680 | AE13: 5900 | AF13: 76.63 | AG13: 0.59 | AH13: 14.92 | AI13: 42.56 | AJ13: 60 | AK13: 9 | AL13: 9 | AM13: 0.74 | AN13: 408 | AO13: 414.64 | AP13: 341493.41 | AQ13: 209458.68 | AR13: 20230124-093759_5e9220f6-d8db-462c-ab1f-046510eb9f5f | AT13: =(AP13-AQ13)/(365*24*2) -> 7.5362289
A14: 20.08 | B14: 28.67 | C14: 5538.31 | D14: 7.6 | E14: [40.37, 40.37] | F14: [20.09, 20.09] | G14: [7.06, 7.06] | H14: [10.0, 10.0] | I14: 0 | J14: 962.54 | K14: =IF(E14=0,0, VALUE(MID(E14,2,FIND(",",E14)-2))+ VALUE(MID(F14,2,FIND(",",F14)-2))+ VALUE(MID(G14,2,FIND(",",G14)-2)) ) -> 67.52 | L14: =IF(E14=0,0, VALUE(MID(E14,FIND(",",E14)+1,FIND("]",E14)-FIND(",",E14)-1))+ VALUE(MID(F14,FIND(",",F14)+1,FIND("]",F14)-FIND(",",F14)-1))+ VALUE(MID(G14,FIND(",",G14)+1,FIND("]",G14)-FIND(",",G14)-1)) ) -> 67.52 | M14: =(K14-L14) -> 0 | N14: 7.37 | O14: 88.83 | P14: 55 | Q14: 20.3 | R14: 8.59 | S14: 14.63 | T14: 5.45 | U14: 5.75 | V14: 3544.52 | W14: 1047.41 | X14: 1180.55 | Y14: 734.7 | Z14: 6.75 | AA14: 1.55 | AB14: 4.49 | AC14: 61.19 | AD14: 680 | AE14: 5900 | AF14: 77.56 | AG14: 0.59 | AH14: 16.32 | AI14: 47.12 | AJ14: 60 | AK14: 9 | AL14: 9 | AM14: 0.67 | AN14: 408 | AO14: 414 | AP14: 389522.74 | AQ14: 389522.74 | AR14: 20230124-093759_c3d9a479-9ca6-4a54-af09-f91d19f3bb51 | AT14: =(AP14-AQ14)/(365*24*2) -> 0
... A251: 21.76 | B251: 30.64 | C251: 5531.05 | D251: 7.6 | E251: [11.41, 30.51] | F251: [24.75, 1.72] | G251: [13.11, 13.11] | H251: [9.98, 6.05] | I251: 0 | J251: 454.09 | K251: =IF(E251=0,0, VALUE(MID(E251,2,FIND(",",E251)-2))+ VALUE(MID(F251,2,FIND(",",F251)-2))+ VALUE(MID(G251,2,FIND(",",G251)-2)) ) -> 49.27 | L251: =IF(E251=0,0, VALUE(MID(E251,FIND(",",E251)+1,FIND("]",E251)-FIND(",",E251)-1))+ VALUE(MID(F251,FIND(",",F251)+1,FIND("]",F251)-FIND(",",F251)-1))+ VALUE(MID(G251,FIND(",",G251)+1,FIND("]",G251)-FIND(",",G251)-1)) ) -> 45.34 | M251: =(K251-L251) -> 3.93 | N251: 7.1 | O251: 89.21 | P251: 87 | Q251: 19.6 | R251: 8.88 | S251: 18.01 | T251: 3.75 | U251: 12.18 | V251: 3539.87 | W251: 1086.05 | X251: 1575.24 | Y251: 838.28 | Z251: 8.15 | AA251: 1.73 | AB251: 4.15 | AC251: 70.29 | AD251: 680 | AE251: 5900 | AF251: 80.15 | AG251: 0.59 | AH251: 7.17 | AI251: 77.95 | AJ251: 60 | AK251: 9 | AL251: 9 | AM251: 0.4 | AN251: 408 | AO251: 411.63 | AP251: 426364.03 | AQ251: 120724.4 | AR251: 20230124-104213_d19a90aa-763e-4b21-946a-1049fee69e12 | AT251: =(AP251-AQ251)/(365*24*2) -> 17.445184

Sheet N3
A1: supply_temp | B1: return_temp | C1: ct_conductivity | D1: ct_ph | E1: Bore | F1: CWRO | G1: BoilerBD | H1: BD | I1: scheme | J1: mu_conductivity | K1: mu_flow(PV) | L1: mu-flow(OV) | M1: m-saving(PV-OV) | N1: mu_ph | O1: cooling_tower_level | P1: relative_humidity | Q1: ambient_temp | R1: delta_temp | S1: wetBulb_temp | T1: approach_temp | U1: cond_coc | V1: ct_tds | W1: ct_ca | X1: ct_alk | Y1: ct_chloride | Z1: flow_cycle | AA1: sat_index | AB1: sta_index | AC1: perf_index | AD1: system_vol | AE1: rec_rate | AF1: evap_loss | AG1: drift_loss | AH1: blowdown_coc | AI1: hold_time_index | AJ1: dosing_residual | AK1: dosing_contact_time | AL1: dosing_density | AM1: dosing_continuous | AN1: dosing_initial | AO1: dosing_slug | AP1: currentOperatingCost | AQ1: newOperatingCost | AR1: updatedDateTime | AS1: Date and Time | AT1: =SUM(AT2:AT251) -> 64.275469 | AU1: Total Savings
A2: 0 | B2: 0 | C2: 0 | D2: 0 | E2: 0 | F2: 0 | G2: 0 | H2: 0 | I2: 0 | J2: 0 | K2: =IF(E2=0,0, VALUE(MID(E2,2,FIND(",",E2)-2))+ VALUE(MID(F2,2,FIND(",",F2)-2))+ VALUE(MID(G2,2,FIND(",",G2)-2)) ) -> 0 | L2: =IF(E2=0,0, VALUE(MID(E2,FIND(",",E2)+1,FIND("]",E2)-FIND(",",E2)-1))+ VALUE(MID(F2,FIND(",",F2)+1,FIND("]",F2)-FIND(",",F2)-1))+ VALUE(MID(G2,FIND(",",G2)+1,FIND("]",G2)-FIND(",",G2)-1)) ) -> 0 | M2: =(K2-L2) -> 0 | N2: 0 | O2: 0 | P2: 0 | Q2: 0 | R2: 0 | S2: 0 | T2: 0 | U2: 0 | V2: 0 | W2: 0 | X2: 0 | Y2: 0 | Z2: 0 | AA2: 0 | AB2: 0 | AC2: 0 | AD2: 0 | AE2: 0 | AF2: 0 | AG2: 0 | AH2: 0 | AI2: 0 | AJ2: 0 | AK2: 0 | AL2: 0 | AM2: 0 | AN2: 0 | AO2: 0 | AP2: 0 | AQ2: 0 | AR2: 0 | AT2: =(AP2-AQ2)/(365*24*2) -> 0 | AU2: =SUM(AT2:AT251) -> 64.275469
A3: 0 | B3: 0 | C3: 0 | D3: 0 | E3: 0 | F3: 0 | G3: 0 | H3: 0 | I3: 0 | J3: 0 | K3: =IF(E3=0,0, VALUE(MID(E3,2,FIND(",",E3)-2))+ VALUE(MID(F3,2,FIND(",",F3)-2))+ VALUE(MID(G3,2,FIND(",",G3)-2)) ) -> 0 | L3: =IF(E3=0,0, VALUE(MID(E3,FIND(",",E3)+1,FIND("]",E3)-FIND(",",E3)-1))+ VALUE(MID(F3,FIND(",",F3)+1,FIND("]",F3)-FIND(",",F3)-1))+ VALUE(MID(G3,FIND(",",G3)+1,FIND("]",G3)-FIND(",",G3)-1)) ) -> 0 | M3: =(K3-L3) -> 0 | N3: 0 | O3: 0 | P3: 0 | Q3: 0 | R3: 0 | S3: 0 | T3: 0 | U3: 0 | V3: 0 | W3: 0 | X3: 0 | Y3: 0 | Z3: 0 | AA3: 0 | AB3: 0 | AC3: 0 | AD3: 0 | AE3: 0 | AF3: 0 | AG3: 0 | AH3: 0 | AI3: 0 | AJ3: 0 | AK3: 0 | AL3: 0 | AM3: 0 | AN3: 0 | AO3: 0 | AP3: 0 | AQ3: 0 | AR3: 0 | AT3: =(AP3-AQ3)/(365*24*2) -> 0
A4: 0 | B4: 0 | C4: 0 | D4: 0 | E4: 0 | F4: 0 | G4: 0 | H4: 0 | I4: 0 | J4: 0 | K4: =IF(E4=0,0, VALUE(MID(E4,2,FIND(",",E4)-2))+ VALUE(MID(F4,2,FIND(",",F4)-2))+ VALUE(MID(G4,2,FIND(",",G4)-2)) ) -> 0 | L4: =IF(E4=0,0, VALUE(MID(E4,FIND(",",E4)+1,FIND("]",E4)-FIND(",",E4)-1))+ VALUE(MID(F4,FIND(",",F4)+1,FIND("]",F4)-FIND(",",F4)-1))+ VALUE(MID(G4,FIND(",",G4)+1,FIND("]",G4)-FIND(",",G4)-1)) ) -> 0 | M4: =(K4-L4) -> 0 | N4: 0 | O4: 0 | P4: 0 | Q4: 0 | R4: 0 | S4: 0 | T4: 0 | U4: 0 | V4: 0 | W4: 0 | X4: 0 | Y4: 0 | Z4: 0 | AA4: 0 | AB4: 0 | AC4: 0 | AD4: 0 | AE4: 0 | AF4: 0 | AG4: 0 | AH4: 0 | AI4: 0 | AJ4: 0 | AK4: 0 | AL4: 0 | AM4: 0 | AN4: 0 | AO4: 0 | AP4: 0 | AQ4: 0 | AR4: 0 | AT4: =(AP4-AQ4)/(365*24*2) -> 0
